<?xml version="1.0" encoding="UTF-8"?>
<!DOCTYPE html PUBLIC "-//W3C//DTD XHTML 1.0 Strict//EN" "http://www.w3.org/TR/xhtml1/DTD/xhtml1-strict.dtd">
<html xmlns="http://www.w3.org/1999/xhtml">
<head>
    <title>测试报告</title>
    <meta name="generator" content="HTMLTestRunner 0.9.1"/>
    <meta http-equiv="Content-Type" content="text/html; charset=UTF-8"/>
    <link href="http://cdn.bootcss.com/bootstrap/3.3.0/css/bootstrap.min.css" rel="stylesheet">
    <script src="https://cdn.bootcss.com/echarts/3.8.5/echarts.common.min.js"></script>
    <!-- <script type="text/javascript" src="js/echarts.common.min.js"></script> -->
    
<style type="text/css" media="screen">
    body        { font-family: Microsoft YaHei,Consolas,arial,sans-serif; font-size: 80%; }
    table       { font-size: 100%; }
    pre         { white-space: pre-wrap;word-wrap: break-word; }
    /* -- heading ---------------------------------------------------------------------- */
    h1 {
        font-size: 16pt;
        color: gray;
    }
    .heading {
        margin-top: 0ex;
        margin-bottom: 1ex;
    }
    .heading .attribute {
        margin-top: 1ex;
        margin-bottom: 0;
    }
    .heading .description {
        margin-top: 2ex;
        margin-bottom: 3ex;
    }
    /* -- css div popup ------------------------------------------------------------------------ */
    a.popup_link {
    }
    a.popup_link:hover {
        color: red;
    }
    .popup_window {
        display: none;
        position: relative;
        left: 0px;
        top: 0px;
        /*border: solid #627173 1px; */
        padding: 10px;
        /*background-color: #E6E6D6; */
        font-family: "Lucida Console", "Courier New", Courier, monospace;
        text-align: left;
        font-size: 8pt;
        /* width: 500px;*/
    }
    }
    /* -- report ------------------------------------------------------------------------ */
    #show_detail_line {
        margin-top: 3ex;
        margin-bottom: 1ex;
    }
    #result_table {
        width: 99%;
    }
    #header_row {
        font-weight: bold;
        color: #303641;
        background-color: #ebebeb;
    }
    #total_row  { font-weight: bold; }
    .passClass  { background-color: #bdedbc; }
    .failClass  { background-color: #ffefa4; }
    .errorClass { background-color: #ffc9c9; }
    .passCase   { color: #6c6; }
    .failCase   { color: #FF6600; font-weight: bold; }
    .errorCase  { color: #c00; font-weight: bold; }
    .hiddenRow  { display: none; }
    .testcase   { margin-left: 2em; }
    /* -- ending ---------------------------------------------------------------------- */
    #ending {
    }
    #div_base {
                position:absolute;
                top:0%;
                left:5%;
                right:5%;
                width: auto;
                height: auto;
                margin: -15px 0 0 0;
    }
</style>

</head>
<body>
    <script language="javascript" type="text/javascript"><!--
    output_list = Array();
    /* level - 0:Summary; 1:Failed; 2:All */
    function showCase(level) {
        trs = document.getElementsByTagName("tr");
        for (var i = 0; i < trs.length; i++) {
            tr = trs[i];
            id = tr.id;
            if (id.substr(0,2) == 'ft') {
                if (level < 1) {
                    tr.className = 'hiddenRow';
                }
                else {
                    tr.className = '';
                }
            }
            if (id.substr(0,2) == 'pt') {
                if (level > 1) {
                    tr.className = '';
                }
                else {
                    tr.className = 'hiddenRow';
                }
            }
        }
    }
    function showClassDetail(cid, count) {
        var id_list = Array(count);
        var toHide = 1;
        for (var i = 0; i < count; i++) {
            tid0 = 't' + cid.substr(1) + '.' + (i+1);
            tid = 'f' + tid0;
            tr = document.getElementById(tid);
            if (!tr) {
                tid = 'p' + tid0;
                tr = document.getElementById(tid);
            }
            id_list[i] = tid;
            if (tr.className) {
                toHide = 0;
            }
        }
        for (var i = 0; i < count; i++) {
            tid = id_list[i];
            if (toHide) {
                document.getElementById('div_'+tid).style.display = 'none'
                document.getElementById(tid).className = 'hiddenRow';
            }
            else {
                document.getElementById(tid).className = '';
            }
        }
    }
    function showTestDetail(div_id){
        var details_div = document.getElementById(div_id)
        var displayState = details_div.style.display
        // alert(displayState)
        if (displayState != 'block' ) {
            displayState = 'block'
            details_div.style.display = 'block'
        }
        else {
            details_div.style.display = 'none'
        }
    }
    function html_escape(s) {
        s = s.replace(/&/g,'&amp;');
        s = s.replace(/</g,'&lt;');
        s = s.replace(/>/g,'&gt;');
        return s;
    }
    /* obsoleted by detail in <div>
    function showOutput(id, name) {
        var w = window.open("", //url
                        name,
                        "resizable,scrollbars,status,width=800,height=450");
        d = w.document;
        d.write("<pre>");
        d.write(html_escape(output_list[id]));
        d.write("\n");
        d.write("<a href='javascript:window.close()'>close</a>\n");
        d.write("</pre>\n");
        d.close();
    }
    */
    --></script>
    <div id="div_base">
        
    <div class='page-header'>
        <h1>测试报告</h1>
    <p class='attribute'><strong>开始时间:</strong> 2021-09-10 14:01:09</p>
<p class='attribute'><strong>运行时长:</strong> 0:00:00.031914</p>
<p class='attribute'><strong>状态:</strong> 错误 19</p>

    </div>
    <div style="float: left;width:50%;"><p class='description'>None</p></div>
    <div id="chart" style="width:50%;height:400px;float:left;"></div>

        
    <div class="btn-group btn-group-sm">
        <button class="btn btn-default" onclick='javascript:showCase(0)'>总结</button>
        <button class="btn btn-default" onclick='javascript:showCase(1)'>失败</button>
        <button class="btn btn-default" onclick='javascript:showCase(2)'>全部</button>
    </div>
    <p></p>
    <table id='result_table' class="table table-bordered">
        <colgroup>
            <col align='left' />
            <col align='right' />
            <col align='right' />
            <col align='right' />
            <col align='right' />
            <col align='right' />
        </colgroup>
        <tr id='header_row'>
            <td>测试套件/测试用例</td>
            <td>总数</td>
            <td>通过</td>
            <td>失败</td>
            <td>错误</td>
            <td>查看</td>
        </tr>
        
    <tr class='errorClass'>
        <td>case.testcase.TestCase</td>
        <td>19</td>
        <td>0</td>
        <td>0</td>
        <td>19</td>
        <td><a href="javascript:showClassDetail('c1',19)">详情</a></td>
    </tr>

<tr id='ft1.1' class='none'>
    <td class='errorCase'><div class='testcase'>test_run_case_01: 执行测试脚本</div></td>
    <td colspan='5' align='center'>
    <!--css div popup start-->
    <a class="popup_link" onfocus='this.blur();' href="javascript:showTestDetail('div_ft1.1')" >
        错误</a>
    <div id='div_ft1.1' class="popup_window">
        <pre>ft1.1: --- Logging error ---
Traceback (most recent call last):
  File "D:\PyApi_heartdub\Number\New_testApi\lib\sendrequest.py", line 26, in send_request
    re = s.request(method=method, url="http://one.heartdub.cn:8082"+url, headers=header, data=body_data)
  File "C:\Users\YuanhuaMu\PycharmProjects\pythonProject\venv\lib\site-packages\requests\sessions.py", line 528, in request
    prep = self.prepare_request(req)
  File "C:\Users\YuanhuaMu\PycharmProjects\pythonProject\venv\lib\site-packages\requests\sessions.py", line 456, in prepare_request
    p.prepare(
  File "C:\Users\YuanhuaMu\PycharmProjects\pythonProject\venv\lib\site-packages\requests\models.py", line 317, in prepare
    self.prepare_headers(headers)
  File "C:\Users\YuanhuaMu\PycharmProjects\pythonProject\venv\lib\site-packages\requests\models.py", line 449, in prepare_headers
    for header in headers.items():
AttributeError: 'str' object has no attribute 'items'

During handling of the above exception, another exception occurred:

Traceback (most recent call last):
  File "C:\Users\YuanhuaMu\AppData\Local\Programs\Python\Python39\lib\logging\__init__.py", line 1083, in emit
    msg = self.format(record)
  File "C:\Users\YuanhuaMu\AppData\Local\Programs\Python\Python39\lib\logging\__init__.py", line 927, in format
    return fmt.format(record)
  File "C:\Users\YuanhuaMu\AppData\Local\Programs\Python\Python39\lib\logging\__init__.py", line 663, in format
    record.message = record.getMessage()
  File "C:\Users\YuanhuaMu\AppData\Local\Programs\Python\Python39\lib\logging\__init__.py", line 367, in getMessage
    msg = msg % self.args
TypeError: not all arguments converted during string formatting
Call stack:
  File "D:\PyApi_heartdub\Number\New_testApi\run_suit.py", line 12, in &lt;module&gt;
    runner.run(suite)
  File "D:\PyApi_heartdub\Number\New_testApi\tools\HTMLTestRunner.py", line 677, in run
    test(result)
  File "C:\Users\YuanhuaMu\AppData\Local\Programs\Python\Python39\lib\unittest\suite.py", line 84, in __call__
    return self.run(*args, **kwds)
  File "C:\Users\YuanhuaMu\AppData\Local\Programs\Python\Python39\lib\unittest\suite.py", line 122, in run
    test(result)
  File "C:\Users\YuanhuaMu\AppData\Local\Programs\Python\Python39\lib\unittest\suite.py", line 84, in __call__
    return self.run(*args, **kwds)
  File "C:\Users\YuanhuaMu\AppData\Local\Programs\Python\Python39\lib\unittest\suite.py", line 122, in run
    test(result)
  File "C:\Users\YuanhuaMu\AppData\Local\Programs\Python\Python39\lib\unittest\case.py", line 653, in __call__
    return self.run(*args, **kwds)
  File "C:\Users\YuanhuaMu\AppData\Local\Programs\Python\Python39\lib\unittest\case.py", line 593, in run
    self._callTestMethod(testMethod)
  File "C:\Users\YuanhuaMu\AppData\Local\Programs\Python\Python39\lib\unittest\case.py", line 550, in _callTestMethod
    method()
  File "C:\Users\YuanhuaMu\PycharmProjects\pythonProject\venv\lib\site-packages\ddt.py", line 182, in wrapper
    return func(self, *args, **kwargs)
  File "D:\PyApi_heartdub\Number\New_testApi\case\testcase.py", line 20, in test_run_case
    self.response = send_request(data)  # 返回response
  File "D:\PyApi_heartdub\Number\New_testApi\lib\sendrequest.py", line 38, in send_request
    logging.error("错误信息",error)
Message: '错误信息'
Arguments: (AttributeError("'str' object has no attribute 'items'"),)
--- Logging error ---
Traceback (most recent call last):
  File "D:\PyApi_heartdub\Number\New_testApi\lib\sendrequest.py", line 26, in send_request
    re = s.request(method=method, url="http://one.heartdub.cn:8082"+url, headers=header, data=body_data)
  File "C:\Users\YuanhuaMu\PycharmProjects\pythonProject\venv\lib\site-packages\requests\sessions.py", line 528, in request
    prep = self.prepare_request(req)
  File "C:\Users\YuanhuaMu\PycharmProjects\pythonProject\venv\lib\site-packages\requests\sessions.py", line 456, in prepare_request
    p.prepare(
  File "C:\Users\YuanhuaMu\PycharmProjects\pythonProject\venv\lib\site-packages\requests\models.py", line 317, in prepare
    self.prepare_headers(headers)
  File "C:\Users\YuanhuaMu\PycharmProjects\pythonProject\venv\lib\site-packages\requests\models.py", line 449, in prepare_headers
    for header in headers.items():
AttributeError: 'str' object has no attribute 'items'

During handling of the above exception, another exception occurred:

Traceback (most recent call last):
  File "C:\Users\YuanhuaMu\AppData\Local\Programs\Python\Python39\lib\logging\__init__.py", line 1083, in emit
    msg = self.format(record)
  File "C:\Users\YuanhuaMu\AppData\Local\Programs\Python\Python39\lib\logging\__init__.py", line 927, in format
    return fmt.format(record)
  File "C:\Users\YuanhuaMu\AppData\Local\Programs\Python\Python39\lib\logging\__init__.py", line 663, in format
    record.message = record.getMessage()
  File "C:\Users\YuanhuaMu\AppData\Local\Programs\Python\Python39\lib\logging\__init__.py", line 367, in getMessage
    msg = msg % self.args
TypeError: not all arguments converted during string formatting
Call stack:
  File "D:\PyApi_heartdub\Number\New_testApi\run_suit.py", line 12, in &lt;module&gt;
    runner.run(suite)
  File "D:\PyApi_heartdub\Number\New_testApi\tools\HTMLTestRunner.py", line 677, in run
    test(result)
  File "C:\Users\YuanhuaMu\AppData\Local\Programs\Python\Python39\lib\unittest\suite.py", line 84, in __call__
    return self.run(*args, **kwds)
  File "C:\Users\YuanhuaMu\AppData\Local\Programs\Python\Python39\lib\unittest\suite.py", line 122, in run
    test(result)
  File "C:\Users\YuanhuaMu\AppData\Local\Programs\Python\Python39\lib\unittest\suite.py", line 84, in __call__
    return self.run(*args, **kwds)
  File "C:\Users\YuanhuaMu\AppData\Local\Programs\Python\Python39\lib\unittest\suite.py", line 122, in run
    test(result)
  File "C:\Users\YuanhuaMu\AppData\Local\Programs\Python\Python39\lib\unittest\case.py", line 653, in __call__
    return self.run(*args, **kwds)
  File "C:\Users\YuanhuaMu\AppData\Local\Programs\Python\Python39\lib\unittest\case.py", line 593, in run
    self._callTestMethod(testMethod)
  File "C:\Users\YuanhuaMu\AppData\Local\Programs\Python\Python39\lib\unittest\case.py", line 550, in _callTestMethod
    method()
  File "C:\Users\YuanhuaMu\PycharmProjects\pythonProject\venv\lib\site-packages\ddt.py", line 182, in wrapper
    return func(self, *args, **kwargs)
  File "D:\PyApi_heartdub\Number\New_testApi\case\testcase.py", line 20, in test_run_case
    self.response = send_request(data)  # 返回response
  File "D:\PyApi_heartdub\Number\New_testApi\lib\sendrequest.py", line 38, in send_request
    logging.error("错误信息",error)
Message: '错误信息'
Arguments: (AttributeError("'str' object has no attribute 'items'"),)
________
Traceback (most recent call last):
  File "C:\Users\YuanhuaMu\PycharmProjects\pythonProject\venv\lib\site-packages\ddt.py", line 182, in wrapper
    return func(self, *args, **kwargs)
  File "D:\PyApi_heartdub\Number\New_testApi\case\testcase.py", line 22, in test_run_case
    logging.info("页面返回信息：%s" % self.response.json())
AttributeError: 'NoneType' object has no attribute 'json'
</pre>
    </div>
    <!--css div popup end-->
    </td>
</tr>

<tr id='ft1.2' class='none'>
    <td class='errorCase'><div class='testcase'>test_run_case_02: 执行测试脚本</div></td>
    <td colspan='5' align='center'>
    <!--css div popup start-->
    <a class="popup_link" onfocus='this.blur();' href="javascript:showTestDetail('div_ft1.2')" >
        错误</a>
    <div id='div_ft1.2' class="popup_window">
        <pre>ft1.2: --- Logging error ---
Traceback (most recent call last):
  File "D:\PyApi_heartdub\Number\New_testApi\lib\sendrequest.py", line 26, in send_request
    re = s.request(method=method, url="http://one.heartdub.cn:8082"+url, headers=header, data=body_data)
  File "C:\Users\YuanhuaMu\PycharmProjects\pythonProject\venv\lib\site-packages\requests\sessions.py", line 528, in request
    prep = self.prepare_request(req)
  File "C:\Users\YuanhuaMu\PycharmProjects\pythonProject\venv\lib\site-packages\requests\sessions.py", line 456, in prepare_request
    p.prepare(
  File "C:\Users\YuanhuaMu\PycharmProjects\pythonProject\venv\lib\site-packages\requests\models.py", line 317, in prepare
    self.prepare_headers(headers)
  File "C:\Users\YuanhuaMu\PycharmProjects\pythonProject\venv\lib\site-packages\requests\models.py", line 449, in prepare_headers
    for header in headers.items():
AttributeError: 'str' object has no attribute 'items'

During handling of the above exception, another exception occurred:

Traceback (most recent call last):
  File "C:\Users\YuanhuaMu\AppData\Local\Programs\Python\Python39\lib\logging\__init__.py", line 1083, in emit
    msg = self.format(record)
  File "C:\Users\YuanhuaMu\AppData\Local\Programs\Python\Python39\lib\logging\__init__.py", line 927, in format
    return fmt.format(record)
  File "C:\Users\YuanhuaMu\AppData\Local\Programs\Python\Python39\lib\logging\__init__.py", line 663, in format
    record.message = record.getMessage()
  File "C:\Users\YuanhuaMu\AppData\Local\Programs\Python\Python39\lib\logging\__init__.py", line 367, in getMessage
    msg = msg % self.args
TypeError: not all arguments converted during string formatting
Call stack:
  File "D:\PyApi_heartdub\Number\New_testApi\run_suit.py", line 12, in &lt;module&gt;
    runner.run(suite)
  File "D:\PyApi_heartdub\Number\New_testApi\tools\HTMLTestRunner.py", line 677, in run
    test(result)
  File "C:\Users\YuanhuaMu\AppData\Local\Programs\Python\Python39\lib\unittest\suite.py", line 84, in __call__
    return self.run(*args, **kwds)
  File "C:\Users\YuanhuaMu\AppData\Local\Programs\Python\Python39\lib\unittest\suite.py", line 122, in run
    test(result)
  File "C:\Users\YuanhuaMu\AppData\Local\Programs\Python\Python39\lib\unittest\suite.py", line 84, in __call__
    return self.run(*args, **kwds)
  File "C:\Users\YuanhuaMu\AppData\Local\Programs\Python\Python39\lib\unittest\suite.py", line 122, in run
    test(result)
  File "C:\Users\YuanhuaMu\AppData\Local\Programs\Python\Python39\lib\unittest\case.py", line 653, in __call__
    return self.run(*args, **kwds)
  File "C:\Users\YuanhuaMu\AppData\Local\Programs\Python\Python39\lib\unittest\case.py", line 593, in run
    self._callTestMethod(testMethod)
  File "C:\Users\YuanhuaMu\AppData\Local\Programs\Python\Python39\lib\unittest\case.py", line 550, in _callTestMethod
    method()
  File "C:\Users\YuanhuaMu\PycharmProjects\pythonProject\venv\lib\site-packages\ddt.py", line 182, in wrapper
    return func(self, *args, **kwargs)
  File "D:\PyApi_heartdub\Number\New_testApi\case\testcase.py", line 20, in test_run_case
    self.response = send_request(data)  # 返回response
  File "D:\PyApi_heartdub\Number\New_testApi\lib\sendrequest.py", line 38, in send_request
    logging.error("错误信息",error)
Message: '错误信息'
Arguments: (AttributeError("'str' object has no attribute 'items'"),)
--- Logging error ---
Traceback (most recent call last):
  File "D:\PyApi_heartdub\Number\New_testApi\lib\sendrequest.py", line 26, in send_request
    re = s.request(method=method, url="http://one.heartdub.cn:8082"+url, headers=header, data=body_data)
  File "C:\Users\YuanhuaMu\PycharmProjects\pythonProject\venv\lib\site-packages\requests\sessions.py", line 528, in request
    prep = self.prepare_request(req)
  File "C:\Users\YuanhuaMu\PycharmProjects\pythonProject\venv\lib\site-packages\requests\sessions.py", line 456, in prepare_request
    p.prepare(
  File "C:\Users\YuanhuaMu\PycharmProjects\pythonProject\venv\lib\site-packages\requests\models.py", line 317, in prepare
    self.prepare_headers(headers)
  File "C:\Users\YuanhuaMu\PycharmProjects\pythonProject\venv\lib\site-packages\requests\models.py", line 449, in prepare_headers
    for header in headers.items():
AttributeError: 'str' object has no attribute 'items'

During handling of the above exception, another exception occurred:

Traceback (most recent call last):
  File "C:\Users\YuanhuaMu\AppData\Local\Programs\Python\Python39\lib\logging\__init__.py", line 1083, in emit
    msg = self.format(record)
  File "C:\Users\YuanhuaMu\AppData\Local\Programs\Python\Python39\lib\logging\__init__.py", line 927, in format
    return fmt.format(record)
  File "C:\Users\YuanhuaMu\AppData\Local\Programs\Python\Python39\lib\logging\__init__.py", line 663, in format
    record.message = record.getMessage()
  File "C:\Users\YuanhuaMu\AppData\Local\Programs\Python\Python39\lib\logging\__init__.py", line 367, in getMessage
    msg = msg % self.args
TypeError: not all arguments converted during string formatting
Call stack:
  File "D:\PyApi_heartdub\Number\New_testApi\run_suit.py", line 12, in &lt;module&gt;
    runner.run(suite)
  File "D:\PyApi_heartdub\Number\New_testApi\tools\HTMLTestRunner.py", line 677, in run
    test(result)
  File "C:\Users\YuanhuaMu\AppData\Local\Programs\Python\Python39\lib\unittest\suite.py", line 84, in __call__
    return self.run(*args, **kwds)
  File "C:\Users\YuanhuaMu\AppData\Local\Programs\Python\Python39\lib\unittest\suite.py", line 122, in run
    test(result)
  File "C:\Users\YuanhuaMu\AppData\Local\Programs\Python\Python39\lib\unittest\suite.py", line 84, in __call__
    return self.run(*args, **kwds)
  File "C:\Users\YuanhuaMu\AppData\Local\Programs\Python\Python39\lib\unittest\suite.py", line 122, in run
    test(result)
  File "C:\Users\YuanhuaMu\AppData\Local\Programs\Python\Python39\lib\unittest\case.py", line 653, in __call__
    return self.run(*args, **kwds)
  File "C:\Users\YuanhuaMu\AppData\Local\Programs\Python\Python39\lib\unittest\case.py", line 593, in run
    self._callTestMethod(testMethod)
  File "C:\Users\YuanhuaMu\AppData\Local\Programs\Python\Python39\lib\unittest\case.py", line 550, in _callTestMethod
    method()
  File "C:\Users\YuanhuaMu\PycharmProjects\pythonProject\venv\lib\site-packages\ddt.py", line 182, in wrapper
    return func(self, *args, **kwargs)
  File "D:\PyApi_heartdub\Number\New_testApi\case\testcase.py", line 20, in test_run_case
    self.response = send_request(data)  # 返回response
  File "D:\PyApi_heartdub\Number\New_testApi\lib\sendrequest.py", line 38, in send_request
    logging.error("错误信息",error)
Message: '错误信息'
Arguments: (AttributeError("'str' object has no attribute 'items'"),)
________
Traceback (most recent call last):
  File "C:\Users\YuanhuaMu\PycharmProjects\pythonProject\venv\lib\site-packages\ddt.py", line 182, in wrapper
    return func(self, *args, **kwargs)
  File "D:\PyApi_heartdub\Number\New_testApi\case\testcase.py", line 22, in test_run_case
    logging.info("页面返回信息：%s" % self.response.json())
AttributeError: 'NoneType' object has no attribute 'json'
</pre>
    </div>
    <!--css div popup end-->
    </td>
</tr>

<tr id='ft1.3' class='none'>
    <td class='errorCase'><div class='testcase'>test_run_case_03: 执行测试脚本</div></td>
    <td colspan='5' align='center'>
    <!--css div popup start-->
    <a class="popup_link" onfocus='this.blur();' href="javascript:showTestDetail('div_ft1.3')" >
        错误</a>
    <div id='div_ft1.3' class="popup_window">
        <pre>ft1.3: --- Logging error ---
Traceback (most recent call last):
  File "D:\PyApi_heartdub\Number\New_testApi\lib\sendrequest.py", line 26, in send_request
    re = s.request(method=method, url="http://one.heartdub.cn:8082"+url, headers=header, data=body_data)
  File "C:\Users\YuanhuaMu\PycharmProjects\pythonProject\venv\lib\site-packages\requests\sessions.py", line 528, in request
    prep = self.prepare_request(req)
  File "C:\Users\YuanhuaMu\PycharmProjects\pythonProject\venv\lib\site-packages\requests\sessions.py", line 456, in prepare_request
    p.prepare(
  File "C:\Users\YuanhuaMu\PycharmProjects\pythonProject\venv\lib\site-packages\requests\models.py", line 317, in prepare
    self.prepare_headers(headers)
  File "C:\Users\YuanhuaMu\PycharmProjects\pythonProject\venv\lib\site-packages\requests\models.py", line 449, in prepare_headers
    for header in headers.items():
AttributeError: 'str' object has no attribute 'items'

During handling of the above exception, another exception occurred:

Traceback (most recent call last):
  File "C:\Users\YuanhuaMu\AppData\Local\Programs\Python\Python39\lib\logging\__init__.py", line 1083, in emit
    msg = self.format(record)
  File "C:\Users\YuanhuaMu\AppData\Local\Programs\Python\Python39\lib\logging\__init__.py", line 927, in format
    return fmt.format(record)
  File "C:\Users\YuanhuaMu\AppData\Local\Programs\Python\Python39\lib\logging\__init__.py", line 663, in format
    record.message = record.getMessage()
  File "C:\Users\YuanhuaMu\AppData\Local\Programs\Python\Python39\lib\logging\__init__.py", line 367, in getMessage
    msg = msg % self.args
TypeError: not all arguments converted during string formatting
Call stack:
  File "D:\PyApi_heartdub\Number\New_testApi\run_suit.py", line 12, in &lt;module&gt;
    runner.run(suite)
  File "D:\PyApi_heartdub\Number\New_testApi\tools\HTMLTestRunner.py", line 677, in run
    test(result)
  File "C:\Users\YuanhuaMu\AppData\Local\Programs\Python\Python39\lib\unittest\suite.py", line 84, in __call__
    return self.run(*args, **kwds)
  File "C:\Users\YuanhuaMu\AppData\Local\Programs\Python\Python39\lib\unittest\suite.py", line 122, in run
    test(result)
  File "C:\Users\YuanhuaMu\AppData\Local\Programs\Python\Python39\lib\unittest\suite.py", line 84, in __call__
    return self.run(*args, **kwds)
  File "C:\Users\YuanhuaMu\AppData\Local\Programs\Python\Python39\lib\unittest\suite.py", line 122, in run
    test(result)
  File "C:\Users\YuanhuaMu\AppData\Local\Programs\Python\Python39\lib\unittest\case.py", line 653, in __call__
    return self.run(*args, **kwds)
  File "C:\Users\YuanhuaMu\AppData\Local\Programs\Python\Python39\lib\unittest\case.py", line 593, in run
    self._callTestMethod(testMethod)
  File "C:\Users\YuanhuaMu\AppData\Local\Programs\Python\Python39\lib\unittest\case.py", line 550, in _callTestMethod
    method()
  File "C:\Users\YuanhuaMu\PycharmProjects\pythonProject\venv\lib\site-packages\ddt.py", line 182, in wrapper
    return func(self, *args, **kwargs)
  File "D:\PyApi_heartdub\Number\New_testApi\case\testcase.py", line 20, in test_run_case
    self.response = send_request(data)  # 返回response
  File "D:\PyApi_heartdub\Number\New_testApi\lib\sendrequest.py", line 38, in send_request
    logging.error("错误信息",error)
Message: '错误信息'
Arguments: (AttributeError("'str' object has no attribute 'items'"),)
--- Logging error ---
Traceback (most recent call last):
  File "D:\PyApi_heartdub\Number\New_testApi\lib\sendrequest.py", line 26, in send_request
    re = s.request(method=method, url="http://one.heartdub.cn:8082"+url, headers=header, data=body_data)
  File "C:\Users\YuanhuaMu\PycharmProjects\pythonProject\venv\lib\site-packages\requests\sessions.py", line 528, in request
    prep = self.prepare_request(req)
  File "C:\Users\YuanhuaMu\PycharmProjects\pythonProject\venv\lib\site-packages\requests\sessions.py", line 456, in prepare_request
    p.prepare(
  File "C:\Users\YuanhuaMu\PycharmProjects\pythonProject\venv\lib\site-packages\requests\models.py", line 317, in prepare
    self.prepare_headers(headers)
  File "C:\Users\YuanhuaMu\PycharmProjects\pythonProject\venv\lib\site-packages\requests\models.py", line 449, in prepare_headers
    for header in headers.items():
AttributeError: 'str' object has no attribute 'items'

During handling of the above exception, another exception occurred:

Traceback (most recent call last):
  File "C:\Users\YuanhuaMu\AppData\Local\Programs\Python\Python39\lib\logging\__init__.py", line 1083, in emit
    msg = self.format(record)
  File "C:\Users\YuanhuaMu\AppData\Local\Programs\Python\Python39\lib\logging\__init__.py", line 927, in format
    return fmt.format(record)
  File "C:\Users\YuanhuaMu\AppData\Local\Programs\Python\Python39\lib\logging\__init__.py", line 663, in format
    record.message = record.getMessage()
  File "C:\Users\YuanhuaMu\AppData\Local\Programs\Python\Python39\lib\logging\__init__.py", line 367, in getMessage
    msg = msg % self.args
TypeError: not all arguments converted during string formatting
Call stack:
  File "D:\PyApi_heartdub\Number\New_testApi\run_suit.py", line 12, in &lt;module&gt;
    runner.run(suite)
  File "D:\PyApi_heartdub\Number\New_testApi\tools\HTMLTestRunner.py", line 677, in run
    test(result)
  File "C:\Users\YuanhuaMu\AppData\Local\Programs\Python\Python39\lib\unittest\suite.py", line 84, in __call__
    return self.run(*args, **kwds)
  File "C:\Users\YuanhuaMu\AppData\Local\Programs\Python\Python39\lib\unittest\suite.py", line 122, in run
    test(result)
  File "C:\Users\YuanhuaMu\AppData\Local\Programs\Python\Python39\lib\unittest\suite.py", line 84, in __call__
    return self.run(*args, **kwds)
  File "C:\Users\YuanhuaMu\AppData\Local\Programs\Python\Python39\lib\unittest\suite.py", line 122, in run
    test(result)
  File "C:\Users\YuanhuaMu\AppData\Local\Programs\Python\Python39\lib\unittest\case.py", line 653, in __call__
    return self.run(*args, **kwds)
  File "C:\Users\YuanhuaMu\AppData\Local\Programs\Python\Python39\lib\unittest\case.py", line 593, in run
    self._callTestMethod(testMethod)
  File "C:\Users\YuanhuaMu\AppData\Local\Programs\Python\Python39\lib\unittest\case.py", line 550, in _callTestMethod
    method()
  File "C:\Users\YuanhuaMu\PycharmProjects\pythonProject\venv\lib\site-packages\ddt.py", line 182, in wrapper
    return func(self, *args, **kwargs)
  File "D:\PyApi_heartdub\Number\New_testApi\case\testcase.py", line 20, in test_run_case
    self.response = send_request(data)  # 返回response
  File "D:\PyApi_heartdub\Number\New_testApi\lib\sendrequest.py", line 38, in send_request
    logging.error("错误信息",error)
Message: '错误信息'
Arguments: (AttributeError("'str' object has no attribute 'items'"),)
________
Traceback (most recent call last):
  File "C:\Users\YuanhuaMu\PycharmProjects\pythonProject\venv\lib\site-packages\ddt.py", line 182, in wrapper
    return func(self, *args, **kwargs)
  File "D:\PyApi_heartdub\Number\New_testApi\case\testcase.py", line 22, in test_run_case
    logging.info("页面返回信息：%s" % self.response.json())
AttributeError: 'NoneType' object has no attribute 'json'
</pre>
    </div>
    <!--css div popup end-->
    </td>
</tr>

<tr id='ft1.4' class='none'>
    <td class='errorCase'><div class='testcase'>test_run_case_04: 执行测试脚本</div></td>
    <td colspan='5' align='center'>
    <!--css div popup start-->
    <a class="popup_link" onfocus='this.blur();' href="javascript:showTestDetail('div_ft1.4')" >
        错误</a>
    <div id='div_ft1.4' class="popup_window">
        <pre>ft1.4: --- Logging error ---
Traceback (most recent call last):
  File "D:\PyApi_heartdub\Number\New_testApi\lib\sendrequest.py", line 26, in send_request
    re = s.request(method=method, url="http://one.heartdub.cn:8082"+url, headers=header, data=body_data)
  File "C:\Users\YuanhuaMu\PycharmProjects\pythonProject\venv\lib\site-packages\requests\sessions.py", line 528, in request
    prep = self.prepare_request(req)
  File "C:\Users\YuanhuaMu\PycharmProjects\pythonProject\venv\lib\site-packages\requests\sessions.py", line 456, in prepare_request
    p.prepare(
  File "C:\Users\YuanhuaMu\PycharmProjects\pythonProject\venv\lib\site-packages\requests\models.py", line 317, in prepare
    self.prepare_headers(headers)
  File "C:\Users\YuanhuaMu\PycharmProjects\pythonProject\venv\lib\site-packages\requests\models.py", line 449, in prepare_headers
    for header in headers.items():
AttributeError: 'str' object has no attribute 'items'

During handling of the above exception, another exception occurred:

Traceback (most recent call last):
  File "C:\Users\YuanhuaMu\AppData\Local\Programs\Python\Python39\lib\logging\__init__.py", line 1083, in emit
    msg = self.format(record)
  File "C:\Users\YuanhuaMu\AppData\Local\Programs\Python\Python39\lib\logging\__init__.py", line 927, in format
    return fmt.format(record)
  File "C:\Users\YuanhuaMu\AppData\Local\Programs\Python\Python39\lib\logging\__init__.py", line 663, in format
    record.message = record.getMessage()
  File "C:\Users\YuanhuaMu\AppData\Local\Programs\Python\Python39\lib\logging\__init__.py", line 367, in getMessage
    msg = msg % self.args
TypeError: not all arguments converted during string formatting
Call stack:
  File "D:\PyApi_heartdub\Number\New_testApi\run_suit.py", line 12, in &lt;module&gt;
    runner.run(suite)
  File "D:\PyApi_heartdub\Number\New_testApi\tools\HTMLTestRunner.py", line 677, in run
    test(result)
  File "C:\Users\YuanhuaMu\AppData\Local\Programs\Python\Python39\lib\unittest\suite.py", line 84, in __call__
    return self.run(*args, **kwds)
  File "C:\Users\YuanhuaMu\AppData\Local\Programs\Python\Python39\lib\unittest\suite.py", line 122, in run
    test(result)
  File "C:\Users\YuanhuaMu\AppData\Local\Programs\Python\Python39\lib\unittest\suite.py", line 84, in __call__
    return self.run(*args, **kwds)
  File "C:\Users\YuanhuaMu\AppData\Local\Programs\Python\Python39\lib\unittest\suite.py", line 122, in run
    test(result)
  File "C:\Users\YuanhuaMu\AppData\Local\Programs\Python\Python39\lib\unittest\case.py", line 653, in __call__
    return self.run(*args, **kwds)
  File "C:\Users\YuanhuaMu\AppData\Local\Programs\Python\Python39\lib\unittest\case.py", line 593, in run
    self._callTestMethod(testMethod)
  File "C:\Users\YuanhuaMu\AppData\Local\Programs\Python\Python39\lib\unittest\case.py", line 550, in _callTestMethod
    method()
  File "C:\Users\YuanhuaMu\PycharmProjects\pythonProject\venv\lib\site-packages\ddt.py", line 182, in wrapper
    return func(self, *args, **kwargs)
  File "D:\PyApi_heartdub\Number\New_testApi\case\testcase.py", line 20, in test_run_case
    self.response = send_request(data)  # 返回response
  File "D:\PyApi_heartdub\Number\New_testApi\lib\sendrequest.py", line 38, in send_request
    logging.error("错误信息",error)
Message: '错误信息'
Arguments: (AttributeError("'str' object has no attribute 'items'"),)
--- Logging error ---
Traceback (most recent call last):
  File "D:\PyApi_heartdub\Number\New_testApi\lib\sendrequest.py", line 26, in send_request
    re = s.request(method=method, url="http://one.heartdub.cn:8082"+url, headers=header, data=body_data)
  File "C:\Users\YuanhuaMu\PycharmProjects\pythonProject\venv\lib\site-packages\requests\sessions.py", line 528, in request
    prep = self.prepare_request(req)
  File "C:\Users\YuanhuaMu\PycharmProjects\pythonProject\venv\lib\site-packages\requests\sessions.py", line 456, in prepare_request
    p.prepare(
  File "C:\Users\YuanhuaMu\PycharmProjects\pythonProject\venv\lib\site-packages\requests\models.py", line 317, in prepare
    self.prepare_headers(headers)
  File "C:\Users\YuanhuaMu\PycharmProjects\pythonProject\venv\lib\site-packages\requests\models.py", line 449, in prepare_headers
    for header in headers.items():
AttributeError: 'str' object has no attribute 'items'

During handling of the above exception, another exception occurred:

Traceback (most recent call last):
  File "C:\Users\YuanhuaMu\AppData\Local\Programs\Python\Python39\lib\logging\__init__.py", line 1083, in emit
    msg = self.format(record)
  File "C:\Users\YuanhuaMu\AppData\Local\Programs\Python\Python39\lib\logging\__init__.py", line 927, in format
    return fmt.format(record)
  File "C:\Users\YuanhuaMu\AppData\Local\Programs\Python\Python39\lib\logging\__init__.py", line 663, in format
    record.message = record.getMessage()
  File "C:\Users\YuanhuaMu\AppData\Local\Programs\Python\Python39\lib\logging\__init__.py", line 367, in getMessage
    msg = msg % self.args
TypeError: not all arguments converted during string formatting
Call stack:
  File "D:\PyApi_heartdub\Number\New_testApi\run_suit.py", line 12, in &lt;module&gt;
    runner.run(suite)
  File "D:\PyApi_heartdub\Number\New_testApi\tools\HTMLTestRunner.py", line 677, in run
    test(result)
  File "C:\Users\YuanhuaMu\AppData\Local\Programs\Python\Python39\lib\unittest\suite.py", line 84, in __call__
    return self.run(*args, **kwds)
  File "C:\Users\YuanhuaMu\AppData\Local\Programs\Python\Python39\lib\unittest\suite.py", line 122, in run
    test(result)
  File "C:\Users\YuanhuaMu\AppData\Local\Programs\Python\Python39\lib\unittest\suite.py", line 84, in __call__
    return self.run(*args, **kwds)
  File "C:\Users\YuanhuaMu\AppData\Local\Programs\Python\Python39\lib\unittest\suite.py", line 122, in run
    test(result)
  File "C:\Users\YuanhuaMu\AppData\Local\Programs\Python\Python39\lib\unittest\case.py", line 653, in __call__
    return self.run(*args, **kwds)
  File "C:\Users\YuanhuaMu\AppData\Local\Programs\Python\Python39\lib\unittest\case.py", line 593, in run
    self._callTestMethod(testMethod)
  File "C:\Users\YuanhuaMu\AppData\Local\Programs\Python\Python39\lib\unittest\case.py", line 550, in _callTestMethod
    method()
  File "C:\Users\YuanhuaMu\PycharmProjects\pythonProject\venv\lib\site-packages\ddt.py", line 182, in wrapper
    return func(self, *args, **kwargs)
  File "D:\PyApi_heartdub\Number\New_testApi\case\testcase.py", line 20, in test_run_case
    self.response = send_request(data)  # 返回response
  File "D:\PyApi_heartdub\Number\New_testApi\lib\sendrequest.py", line 38, in send_request
    logging.error("错误信息",error)
Message: '错误信息'
Arguments: (AttributeError("'str' object has no attribute 'items'"),)
________
Traceback (most recent call last):
  File "C:\Users\YuanhuaMu\PycharmProjects\pythonProject\venv\lib\site-packages\ddt.py", line 182, in wrapper
    return func(self, *args, **kwargs)
  File "D:\PyApi_heartdub\Number\New_testApi\case\testcase.py", line 22, in test_run_case
    logging.info("页面返回信息：%s" % self.response.json())
AttributeError: 'NoneType' object has no attribute 'json'
</pre>
    </div>
    <!--css div popup end-->
    </td>
</tr>

<tr id='ft1.5' class='none'>
    <td class='errorCase'><div class='testcase'>test_run_case_05: 执行测试脚本</div></td>
    <td colspan='5' align='center'>
    <!--css div popup start-->
    <a class="popup_link" onfocus='this.blur();' href="javascript:showTestDetail('div_ft1.5')" >
        错误</a>
    <div id='div_ft1.5' class="popup_window">
        <pre>ft1.5: --- Logging error ---
Traceback (most recent call last):
  File "D:\PyApi_heartdub\Number\New_testApi\lib\sendrequest.py", line 26, in send_request
    re = s.request(method=method, url="http://one.heartdub.cn:8082"+url, headers=header, data=body_data)
  File "C:\Users\YuanhuaMu\PycharmProjects\pythonProject\venv\lib\site-packages\requests\sessions.py", line 528, in request
    prep = self.prepare_request(req)
  File "C:\Users\YuanhuaMu\PycharmProjects\pythonProject\venv\lib\site-packages\requests\sessions.py", line 456, in prepare_request
    p.prepare(
  File "C:\Users\YuanhuaMu\PycharmProjects\pythonProject\venv\lib\site-packages\requests\models.py", line 317, in prepare
    self.prepare_headers(headers)
  File "C:\Users\YuanhuaMu\PycharmProjects\pythonProject\venv\lib\site-packages\requests\models.py", line 449, in prepare_headers
    for header in headers.items():
AttributeError: 'str' object has no attribute 'items'

During handling of the above exception, another exception occurred:

Traceback (most recent call last):
  File "C:\Users\YuanhuaMu\AppData\Local\Programs\Python\Python39\lib\logging\__init__.py", line 1083, in emit
    msg = self.format(record)
  File "C:\Users\YuanhuaMu\AppData\Local\Programs\Python\Python39\lib\logging\__init__.py", line 927, in format
    return fmt.format(record)
  File "C:\Users\YuanhuaMu\AppData\Local\Programs\Python\Python39\lib\logging\__init__.py", line 663, in format
    record.message = record.getMessage()
  File "C:\Users\YuanhuaMu\AppData\Local\Programs\Python\Python39\lib\logging\__init__.py", line 367, in getMessage
    msg = msg % self.args
TypeError: not all arguments converted during string formatting
Call stack:
  File "D:\PyApi_heartdub\Number\New_testApi\run_suit.py", line 12, in &lt;module&gt;
    runner.run(suite)
  File "D:\PyApi_heartdub\Number\New_testApi\tools\HTMLTestRunner.py", line 677, in run
    test(result)
  File "C:\Users\YuanhuaMu\AppData\Local\Programs\Python\Python39\lib\unittest\suite.py", line 84, in __call__
    return self.run(*args, **kwds)
  File "C:\Users\YuanhuaMu\AppData\Local\Programs\Python\Python39\lib\unittest\suite.py", line 122, in run
    test(result)
  File "C:\Users\YuanhuaMu\AppData\Local\Programs\Python\Python39\lib\unittest\suite.py", line 84, in __call__
    return self.run(*args, **kwds)
  File "C:\Users\YuanhuaMu\AppData\Local\Programs\Python\Python39\lib\unittest\suite.py", line 122, in run
    test(result)
  File "C:\Users\YuanhuaMu\AppData\Local\Programs\Python\Python39\lib\unittest\case.py", line 653, in __call__
    return self.run(*args, **kwds)
  File "C:\Users\YuanhuaMu\AppData\Local\Programs\Python\Python39\lib\unittest\case.py", line 593, in run
    self._callTestMethod(testMethod)
  File "C:\Users\YuanhuaMu\AppData\Local\Programs\Python\Python39\lib\unittest\case.py", line 550, in _callTestMethod
    method()
  File "C:\Users\YuanhuaMu\PycharmProjects\pythonProject\venv\lib\site-packages\ddt.py", line 182, in wrapper
    return func(self, *args, **kwargs)
  File "D:\PyApi_heartdub\Number\New_testApi\case\testcase.py", line 20, in test_run_case
    self.response = send_request(data)  # 返回response
  File "D:\PyApi_heartdub\Number\New_testApi\lib\sendrequest.py", line 38, in send_request
    logging.error("错误信息",error)
Message: '错误信息'
Arguments: (AttributeError("'str' object has no attribute 'items'"),)
--- Logging error ---
Traceback (most recent call last):
  File "D:\PyApi_heartdub\Number\New_testApi\lib\sendrequest.py", line 26, in send_request
    re = s.request(method=method, url="http://one.heartdub.cn:8082"+url, headers=header, data=body_data)
  File "C:\Users\YuanhuaMu\PycharmProjects\pythonProject\venv\lib\site-packages\requests\sessions.py", line 528, in request
    prep = self.prepare_request(req)
  File "C:\Users\YuanhuaMu\PycharmProjects\pythonProject\venv\lib\site-packages\requests\sessions.py", line 456, in prepare_request
    p.prepare(
  File "C:\Users\YuanhuaMu\PycharmProjects\pythonProject\venv\lib\site-packages\requests\models.py", line 317, in prepare
    self.prepare_headers(headers)
  File "C:\Users\YuanhuaMu\PycharmProjects\pythonProject\venv\lib\site-packages\requests\models.py", line 449, in prepare_headers
    for header in headers.items():
AttributeError: 'str' object has no attribute 'items'

During handling of the above exception, another exception occurred:

Traceback (most recent call last):
  File "C:\Users\YuanhuaMu\AppData\Local\Programs\Python\Python39\lib\logging\__init__.py", line 1083, in emit
    msg = self.format(record)
  File "C:\Users\YuanhuaMu\AppData\Local\Programs\Python\Python39\lib\logging\__init__.py", line 927, in format
    return fmt.format(record)
  File "C:\Users\YuanhuaMu\AppData\Local\Programs\Python\Python39\lib\logging\__init__.py", line 663, in format
    record.message = record.getMessage()
  File "C:\Users\YuanhuaMu\AppData\Local\Programs\Python\Python39\lib\logging\__init__.py", line 367, in getMessage
    msg = msg % self.args
TypeError: not all arguments converted during string formatting
Call stack:
  File "D:\PyApi_heartdub\Number\New_testApi\run_suit.py", line 12, in &lt;module&gt;
    runner.run(suite)
  File "D:\PyApi_heartdub\Number\New_testApi\tools\HTMLTestRunner.py", line 677, in run
    test(result)
  File "C:\Users\YuanhuaMu\AppData\Local\Programs\Python\Python39\lib\unittest\suite.py", line 84, in __call__
    return self.run(*args, **kwds)
  File "C:\Users\YuanhuaMu\AppData\Local\Programs\Python\Python39\lib\unittest\suite.py", line 122, in run
    test(result)
  File "C:\Users\YuanhuaMu\AppData\Local\Programs\Python\Python39\lib\unittest\suite.py", line 84, in __call__
    return self.run(*args, **kwds)
  File "C:\Users\YuanhuaMu\AppData\Local\Programs\Python\Python39\lib\unittest\suite.py", line 122, in run
    test(result)
  File "C:\Users\YuanhuaMu\AppData\Local\Programs\Python\Python39\lib\unittest\case.py", line 653, in __call__
    return self.run(*args, **kwds)
  File "C:\Users\YuanhuaMu\AppData\Local\Programs\Python\Python39\lib\unittest\case.py", line 593, in run
    self._callTestMethod(testMethod)
  File "C:\Users\YuanhuaMu\AppData\Local\Programs\Python\Python39\lib\unittest\case.py", line 550, in _callTestMethod
    method()
  File "C:\Users\YuanhuaMu\PycharmProjects\pythonProject\venv\lib\site-packages\ddt.py", line 182, in wrapper
    return func(self, *args, **kwargs)
  File "D:\PyApi_heartdub\Number\New_testApi\case\testcase.py", line 20, in test_run_case
    self.response = send_request(data)  # 返回response
  File "D:\PyApi_heartdub\Number\New_testApi\lib\sendrequest.py", line 38, in send_request
    logging.error("错误信息",error)
Message: '错误信息'
Arguments: (AttributeError("'str' object has no attribute 'items'"),)
________
Traceback (most recent call last):
  File "C:\Users\YuanhuaMu\PycharmProjects\pythonProject\venv\lib\site-packages\ddt.py", line 182, in wrapper
    return func(self, *args, **kwargs)
  File "D:\PyApi_heartdub\Number\New_testApi\case\testcase.py", line 22, in test_run_case
    logging.info("页面返回信息：%s" % self.response.json())
AttributeError: 'NoneType' object has no attribute 'json'
</pre>
    </div>
    <!--css div popup end-->
    </td>
</tr>

<tr id='ft1.6' class='none'>
    <td class='errorCase'><div class='testcase'>test_run_case_06: 执行测试脚本</div></td>
    <td colspan='5' align='center'>
    <!--css div popup start-->
    <a class="popup_link" onfocus='this.blur();' href="javascript:showTestDetail('div_ft1.6')" >
        错误</a>
    <div id='div_ft1.6' class="popup_window">
        <pre>ft1.6: --- Logging error ---
Traceback (most recent call last):
  File "D:\PyApi_heartdub\Number\New_testApi\lib\sendrequest.py", line 26, in send_request
    re = s.request(method=method, url="http://one.heartdub.cn:8082"+url, headers=header, data=body_data)
  File "C:\Users\YuanhuaMu\PycharmProjects\pythonProject\venv\lib\site-packages\requests\sessions.py", line 528, in request
    prep = self.prepare_request(req)
  File "C:\Users\YuanhuaMu\PycharmProjects\pythonProject\venv\lib\site-packages\requests\sessions.py", line 456, in prepare_request
    p.prepare(
  File "C:\Users\YuanhuaMu\PycharmProjects\pythonProject\venv\lib\site-packages\requests\models.py", line 317, in prepare
    self.prepare_headers(headers)
  File "C:\Users\YuanhuaMu\PycharmProjects\pythonProject\venv\lib\site-packages\requests\models.py", line 449, in prepare_headers
    for header in headers.items():
AttributeError: 'str' object has no attribute 'items'

During handling of the above exception, another exception occurred:

Traceback (most recent call last):
  File "C:\Users\YuanhuaMu\AppData\Local\Programs\Python\Python39\lib\logging\__init__.py", line 1083, in emit
    msg = self.format(record)
  File "C:\Users\YuanhuaMu\AppData\Local\Programs\Python\Python39\lib\logging\__init__.py", line 927, in format
    return fmt.format(record)
  File "C:\Users\YuanhuaMu\AppData\Local\Programs\Python\Python39\lib\logging\__init__.py", line 663, in format
    record.message = record.getMessage()
  File "C:\Users\YuanhuaMu\AppData\Local\Programs\Python\Python39\lib\logging\__init__.py", line 367, in getMessage
    msg = msg % self.args
TypeError: not all arguments converted during string formatting
Call stack:
  File "D:\PyApi_heartdub\Number\New_testApi\run_suit.py", line 12, in &lt;module&gt;
    runner.run(suite)
  File "D:\PyApi_heartdub\Number\New_testApi\tools\HTMLTestRunner.py", line 677, in run
    test(result)
  File "C:\Users\YuanhuaMu\AppData\Local\Programs\Python\Python39\lib\unittest\suite.py", line 84, in __call__
    return self.run(*args, **kwds)
  File "C:\Users\YuanhuaMu\AppData\Local\Programs\Python\Python39\lib\unittest\suite.py", line 122, in run
    test(result)
  File "C:\Users\YuanhuaMu\AppData\Local\Programs\Python\Python39\lib\unittest\suite.py", line 84, in __call__
    return self.run(*args, **kwds)
  File "C:\Users\YuanhuaMu\AppData\Local\Programs\Python\Python39\lib\unittest\suite.py", line 122, in run
    test(result)
  File "C:\Users\YuanhuaMu\AppData\Local\Programs\Python\Python39\lib\unittest\case.py", line 653, in __call__
    return self.run(*args, **kwds)
  File "C:\Users\YuanhuaMu\AppData\Local\Programs\Python\Python39\lib\unittest\case.py", line 593, in run
    self._callTestMethod(testMethod)
  File "C:\Users\YuanhuaMu\AppData\Local\Programs\Python\Python39\lib\unittest\case.py", line 550, in _callTestMethod
    method()
  File "C:\Users\YuanhuaMu\PycharmProjects\pythonProject\venv\lib\site-packages\ddt.py", line 182, in wrapper
    return func(self, *args, **kwargs)
  File "D:\PyApi_heartdub\Number\New_testApi\case\testcase.py", line 20, in test_run_case
    self.response = send_request(data)  # 返回response
  File "D:\PyApi_heartdub\Number\New_testApi\lib\sendrequest.py", line 38, in send_request
    logging.error("错误信息",error)
Message: '错误信息'
Arguments: (AttributeError("'str' object has no attribute 'items'"),)
--- Logging error ---
Traceback (most recent call last):
  File "D:\PyApi_heartdub\Number\New_testApi\lib\sendrequest.py", line 26, in send_request
    re = s.request(method=method, url="http://one.heartdub.cn:8082"+url, headers=header, data=body_data)
  File "C:\Users\YuanhuaMu\PycharmProjects\pythonProject\venv\lib\site-packages\requests\sessions.py", line 528, in request
    prep = self.prepare_request(req)
  File "C:\Users\YuanhuaMu\PycharmProjects\pythonProject\venv\lib\site-packages\requests\sessions.py", line 456, in prepare_request
    p.prepare(
  File "C:\Users\YuanhuaMu\PycharmProjects\pythonProject\venv\lib\site-packages\requests\models.py", line 317, in prepare
    self.prepare_headers(headers)
  File "C:\Users\YuanhuaMu\PycharmProjects\pythonProject\venv\lib\site-packages\requests\models.py", line 449, in prepare_headers
    for header in headers.items():
AttributeError: 'str' object has no attribute 'items'

During handling of the above exception, another exception occurred:

Traceback (most recent call last):
  File "C:\Users\YuanhuaMu\AppData\Local\Programs\Python\Python39\lib\logging\__init__.py", line 1083, in emit
    msg = self.format(record)
  File "C:\Users\YuanhuaMu\AppData\Local\Programs\Python\Python39\lib\logging\__init__.py", line 927, in format
    return fmt.format(record)
  File "C:\Users\YuanhuaMu\AppData\Local\Programs\Python\Python39\lib\logging\__init__.py", line 663, in format
    record.message = record.getMessage()
  File "C:\Users\YuanhuaMu\AppData\Local\Programs\Python\Python39\lib\logging\__init__.py", line 367, in getMessage
    msg = msg % self.args
TypeError: not all arguments converted during string formatting
Call stack:
  File "D:\PyApi_heartdub\Number\New_testApi\run_suit.py", line 12, in &lt;module&gt;
    runner.run(suite)
  File "D:\PyApi_heartdub\Number\New_testApi\tools\HTMLTestRunner.py", line 677, in run
    test(result)
  File "C:\Users\YuanhuaMu\AppData\Local\Programs\Python\Python39\lib\unittest\suite.py", line 84, in __call__
    return self.run(*args, **kwds)
  File "C:\Users\YuanhuaMu\AppData\Local\Programs\Python\Python39\lib\unittest\suite.py", line 122, in run
    test(result)
  File "C:\Users\YuanhuaMu\AppData\Local\Programs\Python\Python39\lib\unittest\suite.py", line 84, in __call__
    return self.run(*args, **kwds)
  File "C:\Users\YuanhuaMu\AppData\Local\Programs\Python\Python39\lib\unittest\suite.py", line 122, in run
    test(result)
  File "C:\Users\YuanhuaMu\AppData\Local\Programs\Python\Python39\lib\unittest\case.py", line 653, in __call__
    return self.run(*args, **kwds)
  File "C:\Users\YuanhuaMu\AppData\Local\Programs\Python\Python39\lib\unittest\case.py", line 593, in run
    self._callTestMethod(testMethod)
  File "C:\Users\YuanhuaMu\AppData\Local\Programs\Python\Python39\lib\unittest\case.py", line 550, in _callTestMethod
    method()
  File "C:\Users\YuanhuaMu\PycharmProjects\pythonProject\venv\lib\site-packages\ddt.py", line 182, in wrapper
    return func(self, *args, **kwargs)
  File "D:\PyApi_heartdub\Number\New_testApi\case\testcase.py", line 20, in test_run_case
    self.response = send_request(data)  # 返回response
  File "D:\PyApi_heartdub\Number\New_testApi\lib\sendrequest.py", line 38, in send_request
    logging.error("错误信息",error)
Message: '错误信息'
Arguments: (AttributeError("'str' object has no attribute 'items'"),)
________
Traceback (most recent call last):
  File "C:\Users\YuanhuaMu\PycharmProjects\pythonProject\venv\lib\site-packages\ddt.py", line 182, in wrapper
    return func(self, *args, **kwargs)
  File "D:\PyApi_heartdub\Number\New_testApi\case\testcase.py", line 22, in test_run_case
    logging.info("页面返回信息：%s" % self.response.json())
AttributeError: 'NoneType' object has no attribute 'json'
</pre>
    </div>
    <!--css div popup end-->
    </td>
</tr>

<tr id='ft1.7' class='none'>
    <td class='errorCase'><div class='testcase'>test_run_case_07: 执行测试脚本</div></td>
    <td colspan='5' align='center'>
    <!--css div popup start-->
    <a class="popup_link" onfocus='this.blur();' href="javascript:showTestDetail('div_ft1.7')" >
        错误</a>
    <div id='div_ft1.7' class="popup_window">
        <pre>ft1.7: --- Logging error ---
Traceback (most recent call last):
  File "D:\PyApi_heartdub\Number\New_testApi\lib\sendrequest.py", line 26, in send_request
    re = s.request(method=method, url="http://one.heartdub.cn:8082"+url, headers=header, data=body_data)
  File "C:\Users\YuanhuaMu\PycharmProjects\pythonProject\venv\lib\site-packages\requests\sessions.py", line 528, in request
    prep = self.prepare_request(req)
  File "C:\Users\YuanhuaMu\PycharmProjects\pythonProject\venv\lib\site-packages\requests\sessions.py", line 456, in prepare_request
    p.prepare(
  File "C:\Users\YuanhuaMu\PycharmProjects\pythonProject\venv\lib\site-packages\requests\models.py", line 317, in prepare
    self.prepare_headers(headers)
  File "C:\Users\YuanhuaMu\PycharmProjects\pythonProject\venv\lib\site-packages\requests\models.py", line 449, in prepare_headers
    for header in headers.items():
AttributeError: 'str' object has no attribute 'items'

During handling of the above exception, another exception occurred:

Traceback (most recent call last):
  File "C:\Users\YuanhuaMu\AppData\Local\Programs\Python\Python39\lib\logging\__init__.py", line 1083, in emit
    msg = self.format(record)
  File "C:\Users\YuanhuaMu\AppData\Local\Programs\Python\Python39\lib\logging\__init__.py", line 927, in format
    return fmt.format(record)
  File "C:\Users\YuanhuaMu\AppData\Local\Programs\Python\Python39\lib\logging\__init__.py", line 663, in format
    record.message = record.getMessage()
  File "C:\Users\YuanhuaMu\AppData\Local\Programs\Python\Python39\lib\logging\__init__.py", line 367, in getMessage
    msg = msg % self.args
TypeError: not all arguments converted during string formatting
Call stack:
  File "D:\PyApi_heartdub\Number\New_testApi\run_suit.py", line 12, in &lt;module&gt;
    runner.run(suite)
  File "D:\PyApi_heartdub\Number\New_testApi\tools\HTMLTestRunner.py", line 677, in run
    test(result)
  File "C:\Users\YuanhuaMu\AppData\Local\Programs\Python\Python39\lib\unittest\suite.py", line 84, in __call__
    return self.run(*args, **kwds)
  File "C:\Users\YuanhuaMu\AppData\Local\Programs\Python\Python39\lib\unittest\suite.py", line 122, in run
    test(result)
  File "C:\Users\YuanhuaMu\AppData\Local\Programs\Python\Python39\lib\unittest\suite.py", line 84, in __call__
    return self.run(*args, **kwds)
  File "C:\Users\YuanhuaMu\AppData\Local\Programs\Python\Python39\lib\unittest\suite.py", line 122, in run
    test(result)
  File "C:\Users\YuanhuaMu\AppData\Local\Programs\Python\Python39\lib\unittest\case.py", line 653, in __call__
    return self.run(*args, **kwds)
  File "C:\Users\YuanhuaMu\AppData\Local\Programs\Python\Python39\lib\unittest\case.py", line 593, in run
    self._callTestMethod(testMethod)
  File "C:\Users\YuanhuaMu\AppData\Local\Programs\Python\Python39\lib\unittest\case.py", line 550, in _callTestMethod
    method()
  File "C:\Users\YuanhuaMu\PycharmProjects\pythonProject\venv\lib\site-packages\ddt.py", line 182, in wrapper
    return func(self, *args, **kwargs)
  File "D:\PyApi_heartdub\Number\New_testApi\case\testcase.py", line 20, in test_run_case
    self.response = send_request(data)  # 返回response
  File "D:\PyApi_heartdub\Number\New_testApi\lib\sendrequest.py", line 38, in send_request
    logging.error("错误信息",error)
Message: '错误信息'
Arguments: (AttributeError("'str' object has no attribute 'items'"),)
--- Logging error ---
Traceback (most recent call last):
  File "D:\PyApi_heartdub\Number\New_testApi\lib\sendrequest.py", line 26, in send_request
    re = s.request(method=method, url="http://one.heartdub.cn:8082"+url, headers=header, data=body_data)
  File "C:\Users\YuanhuaMu\PycharmProjects\pythonProject\venv\lib\site-packages\requests\sessions.py", line 528, in request
    prep = self.prepare_request(req)
  File "C:\Users\YuanhuaMu\PycharmProjects\pythonProject\venv\lib\site-packages\requests\sessions.py", line 456, in prepare_request
    p.prepare(
  File "C:\Users\YuanhuaMu\PycharmProjects\pythonProject\venv\lib\site-packages\requests\models.py", line 317, in prepare
    self.prepare_headers(headers)
  File "C:\Users\YuanhuaMu\PycharmProjects\pythonProject\venv\lib\site-packages\requests\models.py", line 449, in prepare_headers
    for header in headers.items():
AttributeError: 'str' object has no attribute 'items'

During handling of the above exception, another exception occurred:

Traceback (most recent call last):
  File "C:\Users\YuanhuaMu\AppData\Local\Programs\Python\Python39\lib\logging\__init__.py", line 1083, in emit
    msg = self.format(record)
  File "C:\Users\YuanhuaMu\AppData\Local\Programs\Python\Python39\lib\logging\__init__.py", line 927, in format
    return fmt.format(record)
  File "C:\Users\YuanhuaMu\AppData\Local\Programs\Python\Python39\lib\logging\__init__.py", line 663, in format
    record.message = record.getMessage()
  File "C:\Users\YuanhuaMu\AppData\Local\Programs\Python\Python39\lib\logging\__init__.py", line 367, in getMessage
    msg = msg % self.args
TypeError: not all arguments converted during string formatting
Call stack:
  File "D:\PyApi_heartdub\Number\New_testApi\run_suit.py", line 12, in &lt;module&gt;
    runner.run(suite)
  File "D:\PyApi_heartdub\Number\New_testApi\tools\HTMLTestRunner.py", line 677, in run
    test(result)
  File "C:\Users\YuanhuaMu\AppData\Local\Programs\Python\Python39\lib\unittest\suite.py", line 84, in __call__
    return self.run(*args, **kwds)
  File "C:\Users\YuanhuaMu\AppData\Local\Programs\Python\Python39\lib\unittest\suite.py", line 122, in run
    test(result)
  File "C:\Users\YuanhuaMu\AppData\Local\Programs\Python\Python39\lib\unittest\suite.py", line 84, in __call__
    return self.run(*args, **kwds)
  File "C:\Users\YuanhuaMu\AppData\Local\Programs\Python\Python39\lib\unittest\suite.py", line 122, in run
    test(result)
  File "C:\Users\YuanhuaMu\AppData\Local\Programs\Python\Python39\lib\unittest\case.py", line 653, in __call__
    return self.run(*args, **kwds)
  File "C:\Users\YuanhuaMu\AppData\Local\Programs\Python\Python39\lib\unittest\case.py", line 593, in run
    self._callTestMethod(testMethod)
  File "C:\Users\YuanhuaMu\AppData\Local\Programs\Python\Python39\lib\unittest\case.py", line 550, in _callTestMethod
    method()
  File "C:\Users\YuanhuaMu\PycharmProjects\pythonProject\venv\lib\site-packages\ddt.py", line 182, in wrapper
    return func(self, *args, **kwargs)
  File "D:\PyApi_heartdub\Number\New_testApi\case\testcase.py", line 20, in test_run_case
    self.response = send_request(data)  # 返回response
  File "D:\PyApi_heartdub\Number\New_testApi\lib\sendrequest.py", line 38, in send_request
    logging.error("错误信息",error)
Message: '错误信息'
Arguments: (AttributeError("'str' object has no attribute 'items'"),)
________
Traceback (most recent call last):
  File "C:\Users\YuanhuaMu\PycharmProjects\pythonProject\venv\lib\site-packages\ddt.py", line 182, in wrapper
    return func(self, *args, **kwargs)
  File "D:\PyApi_heartdub\Number\New_testApi\case\testcase.py", line 22, in test_run_case
    logging.info("页面返回信息：%s" % self.response.json())
AttributeError: 'NoneType' object has no attribute 'json'
</pre>
    </div>
    <!--css div popup end-->
    </td>
</tr>

<tr id='ft1.8' class='none'>
    <td class='errorCase'><div class='testcase'>test_run_case_08: 执行测试脚本</div></td>
    <td colspan='5' align='center'>
    <!--css div popup start-->
    <a class="popup_link" onfocus='this.blur();' href="javascript:showTestDetail('div_ft1.8')" >
        错误</a>
    <div id='div_ft1.8' class="popup_window">
        <pre>ft1.8: --- Logging error ---
Traceback (most recent call last):
  File "D:\PyApi_heartdub\Number\New_testApi\lib\sendrequest.py", line 26, in send_request
    re = s.request(method=method, url="http://one.heartdub.cn:8082"+url, headers=header, data=body_data)
  File "C:\Users\YuanhuaMu\PycharmProjects\pythonProject\venv\lib\site-packages\requests\sessions.py", line 528, in request
    prep = self.prepare_request(req)
  File "C:\Users\YuanhuaMu\PycharmProjects\pythonProject\venv\lib\site-packages\requests\sessions.py", line 456, in prepare_request
    p.prepare(
  File "C:\Users\YuanhuaMu\PycharmProjects\pythonProject\venv\lib\site-packages\requests\models.py", line 317, in prepare
    self.prepare_headers(headers)
  File "C:\Users\YuanhuaMu\PycharmProjects\pythonProject\venv\lib\site-packages\requests\models.py", line 449, in prepare_headers
    for header in headers.items():
AttributeError: 'str' object has no attribute 'items'

During handling of the above exception, another exception occurred:

Traceback (most recent call last):
  File "C:\Users\YuanhuaMu\AppData\Local\Programs\Python\Python39\lib\logging\__init__.py", line 1083, in emit
    msg = self.format(record)
  File "C:\Users\YuanhuaMu\AppData\Local\Programs\Python\Python39\lib\logging\__init__.py", line 927, in format
    return fmt.format(record)
  File "C:\Users\YuanhuaMu\AppData\Local\Programs\Python\Python39\lib\logging\__init__.py", line 663, in format
    record.message = record.getMessage()
  File "C:\Users\YuanhuaMu\AppData\Local\Programs\Python\Python39\lib\logging\__init__.py", line 367, in getMessage
    msg = msg % self.args
TypeError: not all arguments converted during string formatting
Call stack:
  File "D:\PyApi_heartdub\Number\New_testApi\run_suit.py", line 12, in &lt;module&gt;
    runner.run(suite)
  File "D:\PyApi_heartdub\Number\New_testApi\tools\HTMLTestRunner.py", line 677, in run
    test(result)
  File "C:\Users\YuanhuaMu\AppData\Local\Programs\Python\Python39\lib\unittest\suite.py", line 84, in __call__
    return self.run(*args, **kwds)
  File "C:\Users\YuanhuaMu\AppData\Local\Programs\Python\Python39\lib\unittest\suite.py", line 122, in run
    test(result)
  File "C:\Users\YuanhuaMu\AppData\Local\Programs\Python\Python39\lib\unittest\suite.py", line 84, in __call__
    return self.run(*args, **kwds)
  File "C:\Users\YuanhuaMu\AppData\Local\Programs\Python\Python39\lib\unittest\suite.py", line 122, in run
    test(result)
  File "C:\Users\YuanhuaMu\AppData\Local\Programs\Python\Python39\lib\unittest\case.py", line 653, in __call__
    return self.run(*args, **kwds)
  File "C:\Users\YuanhuaMu\AppData\Local\Programs\Python\Python39\lib\unittest\case.py", line 593, in run
    self._callTestMethod(testMethod)
  File "C:\Users\YuanhuaMu\AppData\Local\Programs\Python\Python39\lib\unittest\case.py", line 550, in _callTestMethod
    method()
  File "C:\Users\YuanhuaMu\PycharmProjects\pythonProject\venv\lib\site-packages\ddt.py", line 182, in wrapper
    return func(self, *args, **kwargs)
  File "D:\PyApi_heartdub\Number\New_testApi\case\testcase.py", line 20, in test_run_case
    self.response = send_request(data)  # 返回response
  File "D:\PyApi_heartdub\Number\New_testApi\lib\sendrequest.py", line 38, in send_request
    logging.error("错误信息",error)
Message: '错误信息'
Arguments: (AttributeError("'str' object has no attribute 'items'"),)
--- Logging error ---
Traceback (most recent call last):
  File "D:\PyApi_heartdub\Number\New_testApi\lib\sendrequest.py", line 26, in send_request
    re = s.request(method=method, url="http://one.heartdub.cn:8082"+url, headers=header, data=body_data)
  File "C:\Users\YuanhuaMu\PycharmProjects\pythonProject\venv\lib\site-packages\requests\sessions.py", line 528, in request
    prep = self.prepare_request(req)
  File "C:\Users\YuanhuaMu\PycharmProjects\pythonProject\venv\lib\site-packages\requests\sessions.py", line 456, in prepare_request
    p.prepare(
  File "C:\Users\YuanhuaMu\PycharmProjects\pythonProject\venv\lib\site-packages\requests\models.py", line 317, in prepare
    self.prepare_headers(headers)
  File "C:\Users\YuanhuaMu\PycharmProjects\pythonProject\venv\lib\site-packages\requests\models.py", line 449, in prepare_headers
    for header in headers.items():
AttributeError: 'str' object has no attribute 'items'

During handling of the above exception, another exception occurred:

Traceback (most recent call last):
  File "C:\Users\YuanhuaMu\AppData\Local\Programs\Python\Python39\lib\logging\__init__.py", line 1083, in emit
    msg = self.format(record)
  File "C:\Users\YuanhuaMu\AppData\Local\Programs\Python\Python39\lib\logging\__init__.py", line 927, in format
    return fmt.format(record)
  File "C:\Users\YuanhuaMu\AppData\Local\Programs\Python\Python39\lib\logging\__init__.py", line 663, in format
    record.message = record.getMessage()
  File "C:\Users\YuanhuaMu\AppData\Local\Programs\Python\Python39\lib\logging\__init__.py", line 367, in getMessage
    msg = msg % self.args
TypeError: not all arguments converted during string formatting
Call stack:
  File "D:\PyApi_heartdub\Number\New_testApi\run_suit.py", line 12, in &lt;module&gt;
    runner.run(suite)
  File "D:\PyApi_heartdub\Number\New_testApi\tools\HTMLTestRunner.py", line 677, in run
    test(result)
  File "C:\Users\YuanhuaMu\AppData\Local\Programs\Python\Python39\lib\unittest\suite.py", line 84, in __call__
    return self.run(*args, **kwds)
  File "C:\Users\YuanhuaMu\AppData\Local\Programs\Python\Python39\lib\unittest\suite.py", line 122, in run
    test(result)
  File "C:\Users\YuanhuaMu\AppData\Local\Programs\Python\Python39\lib\unittest\suite.py", line 84, in __call__
    return self.run(*args, **kwds)
  File "C:\Users\YuanhuaMu\AppData\Local\Programs\Python\Python39\lib\unittest\suite.py", line 122, in run
    test(result)
  File "C:\Users\YuanhuaMu\AppData\Local\Programs\Python\Python39\lib\unittest\case.py", line 653, in __call__
    return self.run(*args, **kwds)
  File "C:\Users\YuanhuaMu\AppData\Local\Programs\Python\Python39\lib\unittest\case.py", line 593, in run
    self._callTestMethod(testMethod)
  File "C:\Users\YuanhuaMu\AppData\Local\Programs\Python\Python39\lib\unittest\case.py", line 550, in _callTestMethod
    method()
  File "C:\Users\YuanhuaMu\PycharmProjects\pythonProject\venv\lib\site-packages\ddt.py", line 182, in wrapper
    return func(self, *args, **kwargs)
  File "D:\PyApi_heartdub\Number\New_testApi\case\testcase.py", line 20, in test_run_case
    self.response = send_request(data)  # 返回response
  File "D:\PyApi_heartdub\Number\New_testApi\lib\sendrequest.py", line 38, in send_request
    logging.error("错误信息",error)
Message: '错误信息'
Arguments: (AttributeError("'str' object has no attribute 'items'"),)
________
Traceback (most recent call last):
  File "C:\Users\YuanhuaMu\PycharmProjects\pythonProject\venv\lib\site-packages\ddt.py", line 182, in wrapper
    return func(self, *args, **kwargs)
  File "D:\PyApi_heartdub\Number\New_testApi\case\testcase.py", line 22, in test_run_case
    logging.info("页面返回信息：%s" % self.response.json())
AttributeError: 'NoneType' object has no attribute 'json'
</pre>
    </div>
    <!--css div popup end-->
    </td>
</tr>

<tr id='ft1.9' class='none'>
    <td class='errorCase'><div class='testcase'>test_run_case_09: 执行测试脚本</div></td>
    <td colspan='5' align='center'>
    <!--css div popup start-->
    <a class="popup_link" onfocus='this.blur();' href="javascript:showTestDetail('div_ft1.9')" >
        错误</a>
    <div id='div_ft1.9' class="popup_window">
        <pre>ft1.9: --- Logging error ---
Traceback (most recent call last):
  File "D:\PyApi_heartdub\Number\New_testApi\lib\sendrequest.py", line 26, in send_request
    re = s.request(method=method, url="http://one.heartdub.cn:8082"+url, headers=header, data=body_data)
  File "C:\Users\YuanhuaMu\PycharmProjects\pythonProject\venv\lib\site-packages\requests\sessions.py", line 528, in request
    prep = self.prepare_request(req)
  File "C:\Users\YuanhuaMu\PycharmProjects\pythonProject\venv\lib\site-packages\requests\sessions.py", line 456, in prepare_request
    p.prepare(
  File "C:\Users\YuanhuaMu\PycharmProjects\pythonProject\venv\lib\site-packages\requests\models.py", line 317, in prepare
    self.prepare_headers(headers)
  File "C:\Users\YuanhuaMu\PycharmProjects\pythonProject\venv\lib\site-packages\requests\models.py", line 449, in prepare_headers
    for header in headers.items():
AttributeError: 'str' object has no attribute 'items'

During handling of the above exception, another exception occurred:

Traceback (most recent call last):
  File "C:\Users\YuanhuaMu\AppData\Local\Programs\Python\Python39\lib\logging\__init__.py", line 1083, in emit
    msg = self.format(record)
  File "C:\Users\YuanhuaMu\AppData\Local\Programs\Python\Python39\lib\logging\__init__.py", line 927, in format
    return fmt.format(record)
  File "C:\Users\YuanhuaMu\AppData\Local\Programs\Python\Python39\lib\logging\__init__.py", line 663, in format
    record.message = record.getMessage()
  File "C:\Users\YuanhuaMu\AppData\Local\Programs\Python\Python39\lib\logging\__init__.py", line 367, in getMessage
    msg = msg % self.args
TypeError: not all arguments converted during string formatting
Call stack:
  File "D:\PyApi_heartdub\Number\New_testApi\run_suit.py", line 12, in &lt;module&gt;
    runner.run(suite)
  File "D:\PyApi_heartdub\Number\New_testApi\tools\HTMLTestRunner.py", line 677, in run
    test(result)
  File "C:\Users\YuanhuaMu\AppData\Local\Programs\Python\Python39\lib\unittest\suite.py", line 84, in __call__
    return self.run(*args, **kwds)
  File "C:\Users\YuanhuaMu\AppData\Local\Programs\Python\Python39\lib\unittest\suite.py", line 122, in run
    test(result)
  File "C:\Users\YuanhuaMu\AppData\Local\Programs\Python\Python39\lib\unittest\suite.py", line 84, in __call__
    return self.run(*args, **kwds)
  File "C:\Users\YuanhuaMu\AppData\Local\Programs\Python\Python39\lib\unittest\suite.py", line 122, in run
    test(result)
  File "C:\Users\YuanhuaMu\AppData\Local\Programs\Python\Python39\lib\unittest\case.py", line 653, in __call__
    return self.run(*args, **kwds)
  File "C:\Users\YuanhuaMu\AppData\Local\Programs\Python\Python39\lib\unittest\case.py", line 593, in run
    self._callTestMethod(testMethod)
  File "C:\Users\YuanhuaMu\AppData\Local\Programs\Python\Python39\lib\unittest\case.py", line 550, in _callTestMethod
    method()
  File "C:\Users\YuanhuaMu\PycharmProjects\pythonProject\venv\lib\site-packages\ddt.py", line 182, in wrapper
    return func(self, *args, **kwargs)
  File "D:\PyApi_heartdub\Number\New_testApi\case\testcase.py", line 20, in test_run_case
    self.response = send_request(data)  # 返回response
  File "D:\PyApi_heartdub\Number\New_testApi\lib\sendrequest.py", line 38, in send_request
    logging.error("错误信息",error)
Message: '错误信息'
Arguments: (AttributeError("'str' object has no attribute 'items'"),)
--- Logging error ---
Traceback (most recent call last):
  File "D:\PyApi_heartdub\Number\New_testApi\lib\sendrequest.py", line 26, in send_request
    re = s.request(method=method, url="http://one.heartdub.cn:8082"+url, headers=header, data=body_data)
  File "C:\Users\YuanhuaMu\PycharmProjects\pythonProject\venv\lib\site-packages\requests\sessions.py", line 528, in request
    prep = self.prepare_request(req)
  File "C:\Users\YuanhuaMu\PycharmProjects\pythonProject\venv\lib\site-packages\requests\sessions.py", line 456, in prepare_request
    p.prepare(
  File "C:\Users\YuanhuaMu\PycharmProjects\pythonProject\venv\lib\site-packages\requests\models.py", line 317, in prepare
    self.prepare_headers(headers)
  File "C:\Users\YuanhuaMu\PycharmProjects\pythonProject\venv\lib\site-packages\requests\models.py", line 449, in prepare_headers
    for header in headers.items():
AttributeError: 'str' object has no attribute 'items'

During handling of the above exception, another exception occurred:

Traceback (most recent call last):
  File "C:\Users\YuanhuaMu\AppData\Local\Programs\Python\Python39\lib\logging\__init__.py", line 1083, in emit
    msg = self.format(record)
  File "C:\Users\YuanhuaMu\AppData\Local\Programs\Python\Python39\lib\logging\__init__.py", line 927, in format
    return fmt.format(record)
  File "C:\Users\YuanhuaMu\AppData\Local\Programs\Python\Python39\lib\logging\__init__.py", line 663, in format
    record.message = record.getMessage()
  File "C:\Users\YuanhuaMu\AppData\Local\Programs\Python\Python39\lib\logging\__init__.py", line 367, in getMessage
    msg = msg % self.args
TypeError: not all arguments converted during string formatting
Call stack:
  File "D:\PyApi_heartdub\Number\New_testApi\run_suit.py", line 12, in &lt;module&gt;
    runner.run(suite)
  File "D:\PyApi_heartdub\Number\New_testApi\tools\HTMLTestRunner.py", line 677, in run
    test(result)
  File "C:\Users\YuanhuaMu\AppData\Local\Programs\Python\Python39\lib\unittest\suite.py", line 84, in __call__
    return self.run(*args, **kwds)
  File "C:\Users\YuanhuaMu\AppData\Local\Programs\Python\Python39\lib\unittest\suite.py", line 122, in run
    test(result)
  File "C:\Users\YuanhuaMu\AppData\Local\Programs\Python\Python39\lib\unittest\suite.py", line 84, in __call__
    return self.run(*args, **kwds)
  File "C:\Users\YuanhuaMu\AppData\Local\Programs\Python\Python39\lib\unittest\suite.py", line 122, in run
    test(result)
  File "C:\Users\YuanhuaMu\AppData\Local\Programs\Python\Python39\lib\unittest\case.py", line 653, in __call__
    return self.run(*args, **kwds)
  File "C:\Users\YuanhuaMu\AppData\Local\Programs\Python\Python39\lib\unittest\case.py", line 593, in run
    self._callTestMethod(testMethod)
  File "C:\Users\YuanhuaMu\AppData\Local\Programs\Python\Python39\lib\unittest\case.py", line 550, in _callTestMethod
    method()
  File "C:\Users\YuanhuaMu\PycharmProjects\pythonProject\venv\lib\site-packages\ddt.py", line 182, in wrapper
    return func(self, *args, **kwargs)
  File "D:\PyApi_heartdub\Number\New_testApi\case\testcase.py", line 20, in test_run_case
    self.response = send_request(data)  # 返回response
  File "D:\PyApi_heartdub\Number\New_testApi\lib\sendrequest.py", line 38, in send_request
    logging.error("错误信息",error)
Message: '错误信息'
Arguments: (AttributeError("'str' object has no attribute 'items'"),)
________
Traceback (most recent call last):
  File "C:\Users\YuanhuaMu\PycharmProjects\pythonProject\venv\lib\site-packages\ddt.py", line 182, in wrapper
    return func(self, *args, **kwargs)
  File "D:\PyApi_heartdub\Number\New_testApi\case\testcase.py", line 22, in test_run_case
    logging.info("页面返回信息：%s" % self.response.json())
AttributeError: 'NoneType' object has no attribute 'json'
</pre>
    </div>
    <!--css div popup end-->
    </td>
</tr>

<tr id='ft1.10' class='none'>
    <td class='errorCase'><div class='testcase'>test_run_case_10: 执行测试脚本</div></td>
    <td colspan='5' align='center'>
    <!--css div popup start-->
    <a class="popup_link" onfocus='this.blur();' href="javascript:showTestDetail('div_ft1.10')" >
        错误</a>
    <div id='div_ft1.10' class="popup_window">
        <pre>ft1.10: --- Logging error ---
Traceback (most recent call last):
  File "D:\PyApi_heartdub\Number\New_testApi\lib\sendrequest.py", line 26, in send_request
    re = s.request(method=method, url="http://one.heartdub.cn:8082"+url, headers=header, data=body_data)
  File "C:\Users\YuanhuaMu\PycharmProjects\pythonProject\venv\lib\site-packages\requests\sessions.py", line 528, in request
    prep = self.prepare_request(req)
  File "C:\Users\YuanhuaMu\PycharmProjects\pythonProject\venv\lib\site-packages\requests\sessions.py", line 456, in prepare_request
    p.prepare(
  File "C:\Users\YuanhuaMu\PycharmProjects\pythonProject\venv\lib\site-packages\requests\models.py", line 317, in prepare
    self.prepare_headers(headers)
  File "C:\Users\YuanhuaMu\PycharmProjects\pythonProject\venv\lib\site-packages\requests\models.py", line 449, in prepare_headers
    for header in headers.items():
AttributeError: 'str' object has no attribute 'items'

During handling of the above exception, another exception occurred:

Traceback (most recent call last):
  File "C:\Users\YuanhuaMu\AppData\Local\Programs\Python\Python39\lib\logging\__init__.py", line 1083, in emit
    msg = self.format(record)
  File "C:\Users\YuanhuaMu\AppData\Local\Programs\Python\Python39\lib\logging\__init__.py", line 927, in format
    return fmt.format(record)
  File "C:\Users\YuanhuaMu\AppData\Local\Programs\Python\Python39\lib\logging\__init__.py", line 663, in format
    record.message = record.getMessage()
  File "C:\Users\YuanhuaMu\AppData\Local\Programs\Python\Python39\lib\logging\__init__.py", line 367, in getMessage
    msg = msg % self.args
TypeError: not all arguments converted during string formatting
Call stack:
  File "D:\PyApi_heartdub\Number\New_testApi\run_suit.py", line 12, in &lt;module&gt;
    runner.run(suite)
  File "D:\PyApi_heartdub\Number\New_testApi\tools\HTMLTestRunner.py", line 677, in run
    test(result)
  File "C:\Users\YuanhuaMu\AppData\Local\Programs\Python\Python39\lib\unittest\suite.py", line 84, in __call__
    return self.run(*args, **kwds)
  File "C:\Users\YuanhuaMu\AppData\Local\Programs\Python\Python39\lib\unittest\suite.py", line 122, in run
    test(result)
  File "C:\Users\YuanhuaMu\AppData\Local\Programs\Python\Python39\lib\unittest\suite.py", line 84, in __call__
    return self.run(*args, **kwds)
  File "C:\Users\YuanhuaMu\AppData\Local\Programs\Python\Python39\lib\unittest\suite.py", line 122, in run
    test(result)
  File "C:\Users\YuanhuaMu\AppData\Local\Programs\Python\Python39\lib\unittest\case.py", line 653, in __call__
    return self.run(*args, **kwds)
  File "C:\Users\YuanhuaMu\AppData\Local\Programs\Python\Python39\lib\unittest\case.py", line 593, in run
    self._callTestMethod(testMethod)
  File "C:\Users\YuanhuaMu\AppData\Local\Programs\Python\Python39\lib\unittest\case.py", line 550, in _callTestMethod
    method()
  File "C:\Users\YuanhuaMu\PycharmProjects\pythonProject\venv\lib\site-packages\ddt.py", line 182, in wrapper
    return func(self, *args, **kwargs)
  File "D:\PyApi_heartdub\Number\New_testApi\case\testcase.py", line 20, in test_run_case
    self.response = send_request(data)  # 返回response
  File "D:\PyApi_heartdub\Number\New_testApi\lib\sendrequest.py", line 38, in send_request
    logging.error("错误信息",error)
Message: '错误信息'
Arguments: (AttributeError("'str' object has no attribute 'items'"),)
--- Logging error ---
Traceback (most recent call last):
  File "D:\PyApi_heartdub\Number\New_testApi\lib\sendrequest.py", line 26, in send_request
    re = s.request(method=method, url="http://one.heartdub.cn:8082"+url, headers=header, data=body_data)
  File "C:\Users\YuanhuaMu\PycharmProjects\pythonProject\venv\lib\site-packages\requests\sessions.py", line 528, in request
    prep = self.prepare_request(req)
  File "C:\Users\YuanhuaMu\PycharmProjects\pythonProject\venv\lib\site-packages\requests\sessions.py", line 456, in prepare_request
    p.prepare(
  File "C:\Users\YuanhuaMu\PycharmProjects\pythonProject\venv\lib\site-packages\requests\models.py", line 317, in prepare
    self.prepare_headers(headers)
  File "C:\Users\YuanhuaMu\PycharmProjects\pythonProject\venv\lib\site-packages\requests\models.py", line 449, in prepare_headers
    for header in headers.items():
AttributeError: 'str' object has no attribute 'items'

During handling of the above exception, another exception occurred:

Traceback (most recent call last):
  File "C:\Users\YuanhuaMu\AppData\Local\Programs\Python\Python39\lib\logging\__init__.py", line 1083, in emit
    msg = self.format(record)
  File "C:\Users\YuanhuaMu\AppData\Local\Programs\Python\Python39\lib\logging\__init__.py", line 927, in format
    return fmt.format(record)
  File "C:\Users\YuanhuaMu\AppData\Local\Programs\Python\Python39\lib\logging\__init__.py", line 663, in format
    record.message = record.getMessage()
  File "C:\Users\YuanhuaMu\AppData\Local\Programs\Python\Python39\lib\logging\__init__.py", line 367, in getMessage
    msg = msg % self.args
TypeError: not all arguments converted during string formatting
Call stack:
  File "D:\PyApi_heartdub\Number\New_testApi\run_suit.py", line 12, in &lt;module&gt;
    runner.run(suite)
  File "D:\PyApi_heartdub\Number\New_testApi\tools\HTMLTestRunner.py", line 677, in run
    test(result)
  File "C:\Users\YuanhuaMu\AppData\Local\Programs\Python\Python39\lib\unittest\suite.py", line 84, in __call__
    return self.run(*args, **kwds)
  File "C:\Users\YuanhuaMu\AppData\Local\Programs\Python\Python39\lib\unittest\suite.py", line 122, in run
    test(result)
  File "C:\Users\YuanhuaMu\AppData\Local\Programs\Python\Python39\lib\unittest\suite.py", line 84, in __call__
    return self.run(*args, **kwds)
  File "C:\Users\YuanhuaMu\AppData\Local\Programs\Python\Python39\lib\unittest\suite.py", line 122, in run
    test(result)
  File "C:\Users\YuanhuaMu\AppData\Local\Programs\Python\Python39\lib\unittest\case.py", line 653, in __call__
    return self.run(*args, **kwds)
  File "C:\Users\YuanhuaMu\AppData\Local\Programs\Python\Python39\lib\unittest\case.py", line 593, in run
    self._callTestMethod(testMethod)
  File "C:\Users\YuanhuaMu\AppData\Local\Programs\Python\Python39\lib\unittest\case.py", line 550, in _callTestMethod
    method()
  File "C:\Users\YuanhuaMu\PycharmProjects\pythonProject\venv\lib\site-packages\ddt.py", line 182, in wrapper
    return func(self, *args, **kwargs)
  File "D:\PyApi_heartdub\Number\New_testApi\case\testcase.py", line 20, in test_run_case
    self.response = send_request(data)  # 返回response
  File "D:\PyApi_heartdub\Number\New_testApi\lib\sendrequest.py", line 38, in send_request
    logging.error("错误信息",error)
Message: '错误信息'
Arguments: (AttributeError("'str' object has no attribute 'items'"),)
________
Traceback (most recent call last):
  File "C:\Users\YuanhuaMu\PycharmProjects\pythonProject\venv\lib\site-packages\ddt.py", line 182, in wrapper
    return func(self, *args, **kwargs)
  File "D:\PyApi_heartdub\Number\New_testApi\case\testcase.py", line 22, in test_run_case
    logging.info("页面返回信息：%s" % self.response.json())
AttributeError: 'NoneType' object has no attribute 'json'
</pre>
    </div>
    <!--css div popup end-->
    </td>
</tr>

<tr id='ft1.11' class='none'>
    <td class='errorCase'><div class='testcase'>test_run_case_11: 执行测试脚本</div></td>
    <td colspan='5' align='center'>
    <!--css div popup start-->
    <a class="popup_link" onfocus='this.blur();' href="javascript:showTestDetail('div_ft1.11')" >
        错误</a>
    <div id='div_ft1.11' class="popup_window">
        <pre>ft1.11: --- Logging error ---
Traceback (most recent call last):
  File "D:\PyApi_heartdub\Number\New_testApi\lib\sendrequest.py", line 26, in send_request
    re = s.request(method=method, url="http://one.heartdub.cn:8082"+url, headers=header, data=body_data)
  File "C:\Users\YuanhuaMu\PycharmProjects\pythonProject\venv\lib\site-packages\requests\sessions.py", line 528, in request
    prep = self.prepare_request(req)
  File "C:\Users\YuanhuaMu\PycharmProjects\pythonProject\venv\lib\site-packages\requests\sessions.py", line 456, in prepare_request
    p.prepare(
  File "C:\Users\YuanhuaMu\PycharmProjects\pythonProject\venv\lib\site-packages\requests\models.py", line 317, in prepare
    self.prepare_headers(headers)
  File "C:\Users\YuanhuaMu\PycharmProjects\pythonProject\venv\lib\site-packages\requests\models.py", line 449, in prepare_headers
    for header in headers.items():
AttributeError: 'str' object has no attribute 'items'

During handling of the above exception, another exception occurred:

Traceback (most recent call last):
  File "C:\Users\YuanhuaMu\AppData\Local\Programs\Python\Python39\lib\logging\__init__.py", line 1083, in emit
    msg = self.format(record)
  File "C:\Users\YuanhuaMu\AppData\Local\Programs\Python\Python39\lib\logging\__init__.py", line 927, in format
    return fmt.format(record)
  File "C:\Users\YuanhuaMu\AppData\Local\Programs\Python\Python39\lib\logging\__init__.py", line 663, in format
    record.message = record.getMessage()
  File "C:\Users\YuanhuaMu\AppData\Local\Programs\Python\Python39\lib\logging\__init__.py", line 367, in getMessage
    msg = msg % self.args
TypeError: not all arguments converted during string formatting
Call stack:
  File "D:\PyApi_heartdub\Number\New_testApi\run_suit.py", line 12, in &lt;module&gt;
    runner.run(suite)
  File "D:\PyApi_heartdub\Number\New_testApi\tools\HTMLTestRunner.py", line 677, in run
    test(result)
  File "C:\Users\YuanhuaMu\AppData\Local\Programs\Python\Python39\lib\unittest\suite.py", line 84, in __call__
    return self.run(*args, **kwds)
  File "C:\Users\YuanhuaMu\AppData\Local\Programs\Python\Python39\lib\unittest\suite.py", line 122, in run
    test(result)
  File "C:\Users\YuanhuaMu\AppData\Local\Programs\Python\Python39\lib\unittest\suite.py", line 84, in __call__
    return self.run(*args, **kwds)
  File "C:\Users\YuanhuaMu\AppData\Local\Programs\Python\Python39\lib\unittest\suite.py", line 122, in run
    test(result)
  File "C:\Users\YuanhuaMu\AppData\Local\Programs\Python\Python39\lib\unittest\case.py", line 653, in __call__
    return self.run(*args, **kwds)
  File "C:\Users\YuanhuaMu\AppData\Local\Programs\Python\Python39\lib\unittest\case.py", line 593, in run
    self._callTestMethod(testMethod)
  File "C:\Users\YuanhuaMu\AppData\Local\Programs\Python\Python39\lib\unittest\case.py", line 550, in _callTestMethod
    method()
  File "C:\Users\YuanhuaMu\PycharmProjects\pythonProject\venv\lib\site-packages\ddt.py", line 182, in wrapper
    return func(self, *args, **kwargs)
  File "D:\PyApi_heartdub\Number\New_testApi\case\testcase.py", line 20, in test_run_case
    self.response = send_request(data)  # 返回response
  File "D:\PyApi_heartdub\Number\New_testApi\lib\sendrequest.py", line 38, in send_request
    logging.error("错误信息",error)
Message: '错误信息'
Arguments: (AttributeError("'str' object has no attribute 'items'"),)
--- Logging error ---
Traceback (most recent call last):
  File "D:\PyApi_heartdub\Number\New_testApi\lib\sendrequest.py", line 26, in send_request
    re = s.request(method=method, url="http://one.heartdub.cn:8082"+url, headers=header, data=body_data)
  File "C:\Users\YuanhuaMu\PycharmProjects\pythonProject\venv\lib\site-packages\requests\sessions.py", line 528, in request
    prep = self.prepare_request(req)
  File "C:\Users\YuanhuaMu\PycharmProjects\pythonProject\venv\lib\site-packages\requests\sessions.py", line 456, in prepare_request
    p.prepare(
  File "C:\Users\YuanhuaMu\PycharmProjects\pythonProject\venv\lib\site-packages\requests\models.py", line 317, in prepare
    self.prepare_headers(headers)
  File "C:\Users\YuanhuaMu\PycharmProjects\pythonProject\venv\lib\site-packages\requests\models.py", line 449, in prepare_headers
    for header in headers.items():
AttributeError: 'str' object has no attribute 'items'

During handling of the above exception, another exception occurred:

Traceback (most recent call last):
  File "C:\Users\YuanhuaMu\AppData\Local\Programs\Python\Python39\lib\logging\__init__.py", line 1083, in emit
    msg = self.format(record)
  File "C:\Users\YuanhuaMu\AppData\Local\Programs\Python\Python39\lib\logging\__init__.py", line 927, in format
    return fmt.format(record)
  File "C:\Users\YuanhuaMu\AppData\Local\Programs\Python\Python39\lib\logging\__init__.py", line 663, in format
    record.message = record.getMessage()
  File "C:\Users\YuanhuaMu\AppData\Local\Programs\Python\Python39\lib\logging\__init__.py", line 367, in getMessage
    msg = msg % self.args
TypeError: not all arguments converted during string formatting
Call stack:
  File "D:\PyApi_heartdub\Number\New_testApi\run_suit.py", line 12, in &lt;module&gt;
    runner.run(suite)
  File "D:\PyApi_heartdub\Number\New_testApi\tools\HTMLTestRunner.py", line 677, in run
    test(result)
  File "C:\Users\YuanhuaMu\AppData\Local\Programs\Python\Python39\lib\unittest\suite.py", line 84, in __call__
    return self.run(*args, **kwds)
  File "C:\Users\YuanhuaMu\AppData\Local\Programs\Python\Python39\lib\unittest\suite.py", line 122, in run
    test(result)
  File "C:\Users\YuanhuaMu\AppData\Local\Programs\Python\Python39\lib\unittest\suite.py", line 84, in __call__
    return self.run(*args, **kwds)
  File "C:\Users\YuanhuaMu\AppData\Local\Programs\Python\Python39\lib\unittest\suite.py", line 122, in run
    test(result)
  File "C:\Users\YuanhuaMu\AppData\Local\Programs\Python\Python39\lib\unittest\case.py", line 653, in __call__
    return self.run(*args, **kwds)
  File "C:\Users\YuanhuaMu\AppData\Local\Programs\Python\Python39\lib\unittest\case.py", line 593, in run
    self._callTestMethod(testMethod)
  File "C:\Users\YuanhuaMu\AppData\Local\Programs\Python\Python39\lib\unittest\case.py", line 550, in _callTestMethod
    method()
  File "C:\Users\YuanhuaMu\PycharmProjects\pythonProject\venv\lib\site-packages\ddt.py", line 182, in wrapper
    return func(self, *args, **kwargs)
  File "D:\PyApi_heartdub\Number\New_testApi\case\testcase.py", line 20, in test_run_case
    self.response = send_request(data)  # 返回response
  File "D:\PyApi_heartdub\Number\New_testApi\lib\sendrequest.py", line 38, in send_request
    logging.error("错误信息",error)
Message: '错误信息'
Arguments: (AttributeError("'str' object has no attribute 'items'"),)
________
Traceback (most recent call last):
  File "C:\Users\YuanhuaMu\PycharmProjects\pythonProject\venv\lib\site-packages\ddt.py", line 182, in wrapper
    return func(self, *args, **kwargs)
  File "D:\PyApi_heartdub\Number\New_testApi\case\testcase.py", line 22, in test_run_case
    logging.info("页面返回信息：%s" % self.response.json())
AttributeError: 'NoneType' object has no attribute 'json'
</pre>
    </div>
    <!--css div popup end-->
    </td>
</tr>

<tr id='ft1.12' class='none'>
    <td class='errorCase'><div class='testcase'>test_run_case_12: 执行测试脚本</div></td>
    <td colspan='5' align='center'>
    <!--css div popup start-->
    <a class="popup_link" onfocus='this.blur();' href="javascript:showTestDetail('div_ft1.12')" >
        错误</a>
    <div id='div_ft1.12' class="popup_window">
        <pre>ft1.12: --- Logging error ---
Traceback (most recent call last):
  File "D:\PyApi_heartdub\Number\New_testApi\lib\sendrequest.py", line 26, in send_request
    re = s.request(method=method, url="http://one.heartdub.cn:8082"+url, headers=header, data=body_data)
  File "C:\Users\YuanhuaMu\PycharmProjects\pythonProject\venv\lib\site-packages\requests\sessions.py", line 528, in request
    prep = self.prepare_request(req)
  File "C:\Users\YuanhuaMu\PycharmProjects\pythonProject\venv\lib\site-packages\requests\sessions.py", line 456, in prepare_request
    p.prepare(
  File "C:\Users\YuanhuaMu\PycharmProjects\pythonProject\venv\lib\site-packages\requests\models.py", line 317, in prepare
    self.prepare_headers(headers)
  File "C:\Users\YuanhuaMu\PycharmProjects\pythonProject\venv\lib\site-packages\requests\models.py", line 449, in prepare_headers
    for header in headers.items():
AttributeError: 'str' object has no attribute 'items'

During handling of the above exception, another exception occurred:

Traceback (most recent call last):
  File "C:\Users\YuanhuaMu\AppData\Local\Programs\Python\Python39\lib\logging\__init__.py", line 1083, in emit
    msg = self.format(record)
  File "C:\Users\YuanhuaMu\AppData\Local\Programs\Python\Python39\lib\logging\__init__.py", line 927, in format
    return fmt.format(record)
  File "C:\Users\YuanhuaMu\AppData\Local\Programs\Python\Python39\lib\logging\__init__.py", line 663, in format
    record.message = record.getMessage()
  File "C:\Users\YuanhuaMu\AppData\Local\Programs\Python\Python39\lib\logging\__init__.py", line 367, in getMessage
    msg = msg % self.args
TypeError: not all arguments converted during string formatting
Call stack:
  File "D:\PyApi_heartdub\Number\New_testApi\run_suit.py", line 12, in &lt;module&gt;
    runner.run(suite)
  File "D:\PyApi_heartdub\Number\New_testApi\tools\HTMLTestRunner.py", line 677, in run
    test(result)
  File "C:\Users\YuanhuaMu\AppData\Local\Programs\Python\Python39\lib\unittest\suite.py", line 84, in __call__
    return self.run(*args, **kwds)
  File "C:\Users\YuanhuaMu\AppData\Local\Programs\Python\Python39\lib\unittest\suite.py", line 122, in run
    test(result)
  File "C:\Users\YuanhuaMu\AppData\Local\Programs\Python\Python39\lib\unittest\suite.py", line 84, in __call__
    return self.run(*args, **kwds)
  File "C:\Users\YuanhuaMu\AppData\Local\Programs\Python\Python39\lib\unittest\suite.py", line 122, in run
    test(result)
  File "C:\Users\YuanhuaMu\AppData\Local\Programs\Python\Python39\lib\unittest\case.py", line 653, in __call__
    return self.run(*args, **kwds)
  File "C:\Users\YuanhuaMu\AppData\Local\Programs\Python\Python39\lib\unittest\case.py", line 593, in run
    self._callTestMethod(testMethod)
  File "C:\Users\YuanhuaMu\AppData\Local\Programs\Python\Python39\lib\unittest\case.py", line 550, in _callTestMethod
    method()
  File "C:\Users\YuanhuaMu\PycharmProjects\pythonProject\venv\lib\site-packages\ddt.py", line 182, in wrapper
    return func(self, *args, **kwargs)
  File "D:\PyApi_heartdub\Number\New_testApi\case\testcase.py", line 20, in test_run_case
    self.response = send_request(data)  # 返回response
  File "D:\PyApi_heartdub\Number\New_testApi\lib\sendrequest.py", line 38, in send_request
    logging.error("错误信息",error)
Message: '错误信息'
Arguments: (AttributeError("'str' object has no attribute 'items'"),)
--- Logging error ---
Traceback (most recent call last):
  File "D:\PyApi_heartdub\Number\New_testApi\lib\sendrequest.py", line 26, in send_request
    re = s.request(method=method, url="http://one.heartdub.cn:8082"+url, headers=header, data=body_data)
  File "C:\Users\YuanhuaMu\PycharmProjects\pythonProject\venv\lib\site-packages\requests\sessions.py", line 528, in request
    prep = self.prepare_request(req)
  File "C:\Users\YuanhuaMu\PycharmProjects\pythonProject\venv\lib\site-packages\requests\sessions.py", line 456, in prepare_request
    p.prepare(
  File "C:\Users\YuanhuaMu\PycharmProjects\pythonProject\venv\lib\site-packages\requests\models.py", line 317, in prepare
    self.prepare_headers(headers)
  File "C:\Users\YuanhuaMu\PycharmProjects\pythonProject\venv\lib\site-packages\requests\models.py", line 449, in prepare_headers
    for header in headers.items():
AttributeError: 'str' object has no attribute 'items'

During handling of the above exception, another exception occurred:

Traceback (most recent call last):
  File "C:\Users\YuanhuaMu\AppData\Local\Programs\Python\Python39\lib\logging\__init__.py", line 1083, in emit
    msg = self.format(record)
  File "C:\Users\YuanhuaMu\AppData\Local\Programs\Python\Python39\lib\logging\__init__.py", line 927, in format
    return fmt.format(record)
  File "C:\Users\YuanhuaMu\AppData\Local\Programs\Python\Python39\lib\logging\__init__.py", line 663, in format
    record.message = record.getMessage()
  File "C:\Users\YuanhuaMu\AppData\Local\Programs\Python\Python39\lib\logging\__init__.py", line 367, in getMessage
    msg = msg % self.args
TypeError: not all arguments converted during string formatting
Call stack:
  File "D:\PyApi_heartdub\Number\New_testApi\run_suit.py", line 12, in &lt;module&gt;
    runner.run(suite)
  File "D:\PyApi_heartdub\Number\New_testApi\tools\HTMLTestRunner.py", line 677, in run
    test(result)
  File "C:\Users\YuanhuaMu\AppData\Local\Programs\Python\Python39\lib\unittest\suite.py", line 84, in __call__
    return self.run(*args, **kwds)
  File "C:\Users\YuanhuaMu\AppData\Local\Programs\Python\Python39\lib\unittest\suite.py", line 122, in run
    test(result)
  File "C:\Users\YuanhuaMu\AppData\Local\Programs\Python\Python39\lib\unittest\suite.py", line 84, in __call__
    return self.run(*args, **kwds)
  File "C:\Users\YuanhuaMu\AppData\Local\Programs\Python\Python39\lib\unittest\suite.py", line 122, in run
    test(result)
  File "C:\Users\YuanhuaMu\AppData\Local\Programs\Python\Python39\lib\unittest\case.py", line 653, in __call__
    return self.run(*args, **kwds)
  File "C:\Users\YuanhuaMu\AppData\Local\Programs\Python\Python39\lib\unittest\case.py", line 593, in run
    self._callTestMethod(testMethod)
  File "C:\Users\YuanhuaMu\AppData\Local\Programs\Python\Python39\lib\unittest\case.py", line 550, in _callTestMethod
    method()
  File "C:\Users\YuanhuaMu\PycharmProjects\pythonProject\venv\lib\site-packages\ddt.py", line 182, in wrapper
    return func(self, *args, **kwargs)
  File "D:\PyApi_heartdub\Number\New_testApi\case\testcase.py", line 20, in test_run_case
    self.response = send_request(data)  # 返回response
  File "D:\PyApi_heartdub\Number\New_testApi\lib\sendrequest.py", line 38, in send_request
    logging.error("错误信息",error)
Message: '错误信息'
Arguments: (AttributeError("'str' object has no attribute 'items'"),)
________
Traceback (most recent call last):
  File "C:\Users\YuanhuaMu\PycharmProjects\pythonProject\venv\lib\site-packages\ddt.py", line 182, in wrapper
    return func(self, *args, **kwargs)
  File "D:\PyApi_heartdub\Number\New_testApi\case\testcase.py", line 22, in test_run_case
    logging.info("页面返回信息：%s" % self.response.json())
AttributeError: 'NoneType' object has no attribute 'json'
</pre>
    </div>
    <!--css div popup end-->
    </td>
</tr>

<tr id='ft1.13' class='none'>
    <td class='errorCase'><div class='testcase'>test_run_case_13: 执行测试脚本</div></td>
    <td colspan='5' align='center'>
    <!--css div popup start-->
    <a class="popup_link" onfocus='this.blur();' href="javascript:showTestDetail('div_ft1.13')" >
        错误</a>
    <div id='div_ft1.13' class="popup_window">
        <pre>ft1.13: --- Logging error ---
Traceback (most recent call last):
  File "D:\PyApi_heartdub\Number\New_testApi\lib\sendrequest.py", line 26, in send_request
    re = s.request(method=method, url="http://one.heartdub.cn:8082"+url, headers=header, data=body_data)
  File "C:\Users\YuanhuaMu\PycharmProjects\pythonProject\venv\lib\site-packages\requests\sessions.py", line 528, in request
    prep = self.prepare_request(req)
  File "C:\Users\YuanhuaMu\PycharmProjects\pythonProject\venv\lib\site-packages\requests\sessions.py", line 456, in prepare_request
    p.prepare(
  File "C:\Users\YuanhuaMu\PycharmProjects\pythonProject\venv\lib\site-packages\requests\models.py", line 317, in prepare
    self.prepare_headers(headers)
  File "C:\Users\YuanhuaMu\PycharmProjects\pythonProject\venv\lib\site-packages\requests\models.py", line 449, in prepare_headers
    for header in headers.items():
AttributeError: 'str' object has no attribute 'items'

During handling of the above exception, another exception occurred:

Traceback (most recent call last):
  File "C:\Users\YuanhuaMu\AppData\Local\Programs\Python\Python39\lib\logging\__init__.py", line 1083, in emit
    msg = self.format(record)
  File "C:\Users\YuanhuaMu\AppData\Local\Programs\Python\Python39\lib\logging\__init__.py", line 927, in format
    return fmt.format(record)
  File "C:\Users\YuanhuaMu\AppData\Local\Programs\Python\Python39\lib\logging\__init__.py", line 663, in format
    record.message = record.getMessage()
  File "C:\Users\YuanhuaMu\AppData\Local\Programs\Python\Python39\lib\logging\__init__.py", line 367, in getMessage
    msg = msg % self.args
TypeError: not all arguments converted during string formatting
Call stack:
  File "D:\PyApi_heartdub\Number\New_testApi\run_suit.py", line 12, in &lt;module&gt;
    runner.run(suite)
  File "D:\PyApi_heartdub\Number\New_testApi\tools\HTMLTestRunner.py", line 677, in run
    test(result)
  File "C:\Users\YuanhuaMu\AppData\Local\Programs\Python\Python39\lib\unittest\suite.py", line 84, in __call__
    return self.run(*args, **kwds)
  File "C:\Users\YuanhuaMu\AppData\Local\Programs\Python\Python39\lib\unittest\suite.py", line 122, in run
    test(result)
  File "C:\Users\YuanhuaMu\AppData\Local\Programs\Python\Python39\lib\unittest\suite.py", line 84, in __call__
    return self.run(*args, **kwds)
  File "C:\Users\YuanhuaMu\AppData\Local\Programs\Python\Python39\lib\unittest\suite.py", line 122, in run
    test(result)
  File "C:\Users\YuanhuaMu\AppData\Local\Programs\Python\Python39\lib\unittest\case.py", line 653, in __call__
    return self.run(*args, **kwds)
  File "C:\Users\YuanhuaMu\AppData\Local\Programs\Python\Python39\lib\unittest\case.py", line 593, in run
    self._callTestMethod(testMethod)
  File "C:\Users\YuanhuaMu\AppData\Local\Programs\Python\Python39\lib\unittest\case.py", line 550, in _callTestMethod
    method()
  File "C:\Users\YuanhuaMu\PycharmProjects\pythonProject\venv\lib\site-packages\ddt.py", line 182, in wrapper
    return func(self, *args, **kwargs)
  File "D:\PyApi_heartdub\Number\New_testApi\case\testcase.py", line 20, in test_run_case
    self.response = send_request(data)  # 返回response
  File "D:\PyApi_heartdub\Number\New_testApi\lib\sendrequest.py", line 38, in send_request
    logging.error("错误信息",error)
Message: '错误信息'
Arguments: (AttributeError("'str' object has no attribute 'items'"),)
--- Logging error ---
Traceback (most recent call last):
  File "D:\PyApi_heartdub\Number\New_testApi\lib\sendrequest.py", line 26, in send_request
    re = s.request(method=method, url="http://one.heartdub.cn:8082"+url, headers=header, data=body_data)
  File "C:\Users\YuanhuaMu\PycharmProjects\pythonProject\venv\lib\site-packages\requests\sessions.py", line 528, in request
    prep = self.prepare_request(req)
  File "C:\Users\YuanhuaMu\PycharmProjects\pythonProject\venv\lib\site-packages\requests\sessions.py", line 456, in prepare_request
    p.prepare(
  File "C:\Users\YuanhuaMu\PycharmProjects\pythonProject\venv\lib\site-packages\requests\models.py", line 317, in prepare
    self.prepare_headers(headers)
  File "C:\Users\YuanhuaMu\PycharmProjects\pythonProject\venv\lib\site-packages\requests\models.py", line 449, in prepare_headers
    for header in headers.items():
AttributeError: 'str' object has no attribute 'items'

During handling of the above exception, another exception occurred:

Traceback (most recent call last):
  File "C:\Users\YuanhuaMu\AppData\Local\Programs\Python\Python39\lib\logging\__init__.py", line 1083, in emit
    msg = self.format(record)
  File "C:\Users\YuanhuaMu\AppData\Local\Programs\Python\Python39\lib\logging\__init__.py", line 927, in format
    return fmt.format(record)
  File "C:\Users\YuanhuaMu\AppData\Local\Programs\Python\Python39\lib\logging\__init__.py", line 663, in format
    record.message = record.getMessage()
  File "C:\Users\YuanhuaMu\AppData\Local\Programs\Python\Python39\lib\logging\__init__.py", line 367, in getMessage
    msg = msg % self.args
TypeError: not all arguments converted during string formatting
Call stack:
  File "D:\PyApi_heartdub\Number\New_testApi\run_suit.py", line 12, in &lt;module&gt;
    runner.run(suite)
  File "D:\PyApi_heartdub\Number\New_testApi\tools\HTMLTestRunner.py", line 677, in run
    test(result)
  File "C:\Users\YuanhuaMu\AppData\Local\Programs\Python\Python39\lib\unittest\suite.py", line 84, in __call__
    return self.run(*args, **kwds)
  File "C:\Users\YuanhuaMu\AppData\Local\Programs\Python\Python39\lib\unittest\suite.py", line 122, in run
    test(result)
  File "C:\Users\YuanhuaMu\AppData\Local\Programs\Python\Python39\lib\unittest\suite.py", line 84, in __call__
    return self.run(*args, **kwds)
  File "C:\Users\YuanhuaMu\AppData\Local\Programs\Python\Python39\lib\unittest\suite.py", line 122, in run
    test(result)
  File "C:\Users\YuanhuaMu\AppData\Local\Programs\Python\Python39\lib\unittest\case.py", line 653, in __call__
    return self.run(*args, **kwds)
  File "C:\Users\YuanhuaMu\AppData\Local\Programs\Python\Python39\lib\unittest\case.py", line 593, in run
    self._callTestMethod(testMethod)
  File "C:\Users\YuanhuaMu\AppData\Local\Programs\Python\Python39\lib\unittest\case.py", line 550, in _callTestMethod
    method()
  File "C:\Users\YuanhuaMu\PycharmProjects\pythonProject\venv\lib\site-packages\ddt.py", line 182, in wrapper
    return func(self, *args, **kwargs)
  File "D:\PyApi_heartdub\Number\New_testApi\case\testcase.py", line 20, in test_run_case
    self.response = send_request(data)  # 返回response
  File "D:\PyApi_heartdub\Number\New_testApi\lib\sendrequest.py", line 38, in send_request
    logging.error("错误信息",error)
Message: '错误信息'
Arguments: (AttributeError("'str' object has no attribute 'items'"),)
________
Traceback (most recent call last):
  File "C:\Users\YuanhuaMu\PycharmProjects\pythonProject\venv\lib\site-packages\ddt.py", line 182, in wrapper
    return func(self, *args, **kwargs)
  File "D:\PyApi_heartdub\Number\New_testApi\case\testcase.py", line 22, in test_run_case
    logging.info("页面返回信息：%s" % self.response.json())
AttributeError: 'NoneType' object has no attribute 'json'
</pre>
    </div>
    <!--css div popup end-->
    </td>
</tr>

<tr id='ft1.14' class='none'>
    <td class='errorCase'><div class='testcase'>test_run_case_14: 执行测试脚本</div></td>
    <td colspan='5' align='center'>
    <!--css div popup start-->
    <a class="popup_link" onfocus='this.blur();' href="javascript:showTestDetail('div_ft1.14')" >
        错误</a>
    <div id='div_ft1.14' class="popup_window">
        <pre>ft1.14: --- Logging error ---
Traceback (most recent call last):
  File "D:\PyApi_heartdub\Number\New_testApi\lib\sendrequest.py", line 26, in send_request
    re = s.request(method=method, url="http://one.heartdub.cn:8082"+url, headers=header, data=body_data)
  File "C:\Users\YuanhuaMu\PycharmProjects\pythonProject\venv\lib\site-packages\requests\sessions.py", line 528, in request
    prep = self.prepare_request(req)
  File "C:\Users\YuanhuaMu\PycharmProjects\pythonProject\venv\lib\site-packages\requests\sessions.py", line 456, in prepare_request
    p.prepare(
  File "C:\Users\YuanhuaMu\PycharmProjects\pythonProject\venv\lib\site-packages\requests\models.py", line 317, in prepare
    self.prepare_headers(headers)
  File "C:\Users\YuanhuaMu\PycharmProjects\pythonProject\venv\lib\site-packages\requests\models.py", line 449, in prepare_headers
    for header in headers.items():
AttributeError: 'str' object has no attribute 'items'

During handling of the above exception, another exception occurred:

Traceback (most recent call last):
  File "C:\Users\YuanhuaMu\AppData\Local\Programs\Python\Python39\lib\logging\__init__.py", line 1083, in emit
    msg = self.format(record)
  File "C:\Users\YuanhuaMu\AppData\Local\Programs\Python\Python39\lib\logging\__init__.py", line 927, in format
    return fmt.format(record)
  File "C:\Users\YuanhuaMu\AppData\Local\Programs\Python\Python39\lib\logging\__init__.py", line 663, in format
    record.message = record.getMessage()
  File "C:\Users\YuanhuaMu\AppData\Local\Programs\Python\Python39\lib\logging\__init__.py", line 367, in getMessage
    msg = msg % self.args
TypeError: not all arguments converted during string formatting
Call stack:
  File "D:\PyApi_heartdub\Number\New_testApi\run_suit.py", line 12, in &lt;module&gt;
    runner.run(suite)
  File "D:\PyApi_heartdub\Number\New_testApi\tools\HTMLTestRunner.py", line 677, in run
    test(result)
  File "C:\Users\YuanhuaMu\AppData\Local\Programs\Python\Python39\lib\unittest\suite.py", line 84, in __call__
    return self.run(*args, **kwds)
  File "C:\Users\YuanhuaMu\AppData\Local\Programs\Python\Python39\lib\unittest\suite.py", line 122, in run
    test(result)
  File "C:\Users\YuanhuaMu\AppData\Local\Programs\Python\Python39\lib\unittest\suite.py", line 84, in __call__
    return self.run(*args, **kwds)
  File "C:\Users\YuanhuaMu\AppData\Local\Programs\Python\Python39\lib\unittest\suite.py", line 122, in run
    test(result)
  File "C:\Users\YuanhuaMu\AppData\Local\Programs\Python\Python39\lib\unittest\case.py", line 653, in __call__
    return self.run(*args, **kwds)
  File "C:\Users\YuanhuaMu\AppData\Local\Programs\Python\Python39\lib\unittest\case.py", line 593, in run
    self._callTestMethod(testMethod)
  File "C:\Users\YuanhuaMu\AppData\Local\Programs\Python\Python39\lib\unittest\case.py", line 550, in _callTestMethod
    method()
  File "C:\Users\YuanhuaMu\PycharmProjects\pythonProject\venv\lib\site-packages\ddt.py", line 182, in wrapper
    return func(self, *args, **kwargs)
  File "D:\PyApi_heartdub\Number\New_testApi\case\testcase.py", line 20, in test_run_case
    self.response = send_request(data)  # 返回response
  File "D:\PyApi_heartdub\Number\New_testApi\lib\sendrequest.py", line 38, in send_request
    logging.error("错误信息",error)
Message: '错误信息'
Arguments: (AttributeError("'str' object has no attribute 'items'"),)
--- Logging error ---
Traceback (most recent call last):
  File "D:\PyApi_heartdub\Number\New_testApi\lib\sendrequest.py", line 26, in send_request
    re = s.request(method=method, url="http://one.heartdub.cn:8082"+url, headers=header, data=body_data)
  File "C:\Users\YuanhuaMu\PycharmProjects\pythonProject\venv\lib\site-packages\requests\sessions.py", line 528, in request
    prep = self.prepare_request(req)
  File "C:\Users\YuanhuaMu\PycharmProjects\pythonProject\venv\lib\site-packages\requests\sessions.py", line 456, in prepare_request
    p.prepare(
  File "C:\Users\YuanhuaMu\PycharmProjects\pythonProject\venv\lib\site-packages\requests\models.py", line 317, in prepare
    self.prepare_headers(headers)
  File "C:\Users\YuanhuaMu\PycharmProjects\pythonProject\venv\lib\site-packages\requests\models.py", line 449, in prepare_headers
    for header in headers.items():
AttributeError: 'str' object has no attribute 'items'

During handling of the above exception, another exception occurred:

Traceback (most recent call last):
  File "C:\Users\YuanhuaMu\AppData\Local\Programs\Python\Python39\lib\logging\__init__.py", line 1083, in emit
    msg = self.format(record)
  File "C:\Users\YuanhuaMu\AppData\Local\Programs\Python\Python39\lib\logging\__init__.py", line 927, in format
    return fmt.format(record)
  File "C:\Users\YuanhuaMu\AppData\Local\Programs\Python\Python39\lib\logging\__init__.py", line 663, in format
    record.message = record.getMessage()
  File "C:\Users\YuanhuaMu\AppData\Local\Programs\Python\Python39\lib\logging\__init__.py", line 367, in getMessage
    msg = msg % self.args
TypeError: not all arguments converted during string formatting
Call stack:
  File "D:\PyApi_heartdub\Number\New_testApi\run_suit.py", line 12, in &lt;module&gt;
    runner.run(suite)
  File "D:\PyApi_heartdub\Number\New_testApi\tools\HTMLTestRunner.py", line 677, in run
    test(result)
  File "C:\Users\YuanhuaMu\AppData\Local\Programs\Python\Python39\lib\unittest\suite.py", line 84, in __call__
    return self.run(*args, **kwds)
  File "C:\Users\YuanhuaMu\AppData\Local\Programs\Python\Python39\lib\unittest\suite.py", line 122, in run
    test(result)
  File "C:\Users\YuanhuaMu\AppData\Local\Programs\Python\Python39\lib\unittest\suite.py", line 84, in __call__
    return self.run(*args, **kwds)
  File "C:\Users\YuanhuaMu\AppData\Local\Programs\Python\Python39\lib\unittest\suite.py", line 122, in run
    test(result)
  File "C:\Users\YuanhuaMu\AppData\Local\Programs\Python\Python39\lib\unittest\case.py", line 653, in __call__
    return self.run(*args, **kwds)
  File "C:\Users\YuanhuaMu\AppData\Local\Programs\Python\Python39\lib\unittest\case.py", line 593, in run
    self._callTestMethod(testMethod)
  File "C:\Users\YuanhuaMu\AppData\Local\Programs\Python\Python39\lib\unittest\case.py", line 550, in _callTestMethod
    method()
  File "C:\Users\YuanhuaMu\PycharmProjects\pythonProject\venv\lib\site-packages\ddt.py", line 182, in wrapper
    return func(self, *args, **kwargs)
  File "D:\PyApi_heartdub\Number\New_testApi\case\testcase.py", line 20, in test_run_case
    self.response = send_request(data)  # 返回response
  File "D:\PyApi_heartdub\Number\New_testApi\lib\sendrequest.py", line 38, in send_request
    logging.error("错误信息",error)
Message: '错误信息'
Arguments: (AttributeError("'str' object has no attribute 'items'"),)
________
Traceback (most recent call last):
  File "C:\Users\YuanhuaMu\PycharmProjects\pythonProject\venv\lib\site-packages\ddt.py", line 182, in wrapper
    return func(self, *args, **kwargs)
  File "D:\PyApi_heartdub\Number\New_testApi\case\testcase.py", line 22, in test_run_case
    logging.info("页面返回信息：%s" % self.response.json())
AttributeError: 'NoneType' object has no attribute 'json'
</pre>
    </div>
    <!--css div popup end-->
    </td>
</tr>

<tr id='ft1.15' class='none'>
    <td class='errorCase'><div class='testcase'>test_run_case_15: 执行测试脚本</div></td>
    <td colspan='5' align='center'>
    <!--css div popup start-->
    <a class="popup_link" onfocus='this.blur();' href="javascript:showTestDetail('div_ft1.15')" >
        错误</a>
    <div id='div_ft1.15' class="popup_window">
        <pre>ft1.15: --- Logging error ---
Traceback (most recent call last):
  File "D:\PyApi_heartdub\Number\New_testApi\lib\sendrequest.py", line 26, in send_request
    re = s.request(method=method, url="http://one.heartdub.cn:8082"+url, headers=header, data=body_data)
  File "C:\Users\YuanhuaMu\PycharmProjects\pythonProject\venv\lib\site-packages\requests\sessions.py", line 528, in request
    prep = self.prepare_request(req)
  File "C:\Users\YuanhuaMu\PycharmProjects\pythonProject\venv\lib\site-packages\requests\sessions.py", line 456, in prepare_request
    p.prepare(
  File "C:\Users\YuanhuaMu\PycharmProjects\pythonProject\venv\lib\site-packages\requests\models.py", line 317, in prepare
    self.prepare_headers(headers)
  File "C:\Users\YuanhuaMu\PycharmProjects\pythonProject\venv\lib\site-packages\requests\models.py", line 449, in prepare_headers
    for header in headers.items():
AttributeError: 'str' object has no attribute 'items'

During handling of the above exception, another exception occurred:

Traceback (most recent call last):
  File "C:\Users\YuanhuaMu\AppData\Local\Programs\Python\Python39\lib\logging\__init__.py", line 1083, in emit
    msg = self.format(record)
  File "C:\Users\YuanhuaMu\AppData\Local\Programs\Python\Python39\lib\logging\__init__.py", line 927, in format
    return fmt.format(record)
  File "C:\Users\YuanhuaMu\AppData\Local\Programs\Python\Python39\lib\logging\__init__.py", line 663, in format
    record.message = record.getMessage()
  File "C:\Users\YuanhuaMu\AppData\Local\Programs\Python\Python39\lib\logging\__init__.py", line 367, in getMessage
    msg = msg % self.args
TypeError: not all arguments converted during string formatting
Call stack:
  File "D:\PyApi_heartdub\Number\New_testApi\run_suit.py", line 12, in &lt;module&gt;
    runner.run(suite)
  File "D:\PyApi_heartdub\Number\New_testApi\tools\HTMLTestRunner.py", line 677, in run
    test(result)
  File "C:\Users\YuanhuaMu\AppData\Local\Programs\Python\Python39\lib\unittest\suite.py", line 84, in __call__
    return self.run(*args, **kwds)
  File "C:\Users\YuanhuaMu\AppData\Local\Programs\Python\Python39\lib\unittest\suite.py", line 122, in run
    test(result)
  File "C:\Users\YuanhuaMu\AppData\Local\Programs\Python\Python39\lib\unittest\suite.py", line 84, in __call__
    return self.run(*args, **kwds)
  File "C:\Users\YuanhuaMu\AppData\Local\Programs\Python\Python39\lib\unittest\suite.py", line 122, in run
    test(result)
  File "C:\Users\YuanhuaMu\AppData\Local\Programs\Python\Python39\lib\unittest\case.py", line 653, in __call__
    return self.run(*args, **kwds)
  File "C:\Users\YuanhuaMu\AppData\Local\Programs\Python\Python39\lib\unittest\case.py", line 593, in run
    self._callTestMethod(testMethod)
  File "C:\Users\YuanhuaMu\AppData\Local\Programs\Python\Python39\lib\unittest\case.py", line 550, in _callTestMethod
    method()
  File "C:\Users\YuanhuaMu\PycharmProjects\pythonProject\venv\lib\site-packages\ddt.py", line 182, in wrapper
    return func(self, *args, **kwargs)
  File "D:\PyApi_heartdub\Number\New_testApi\case\testcase.py", line 20, in test_run_case
    self.response = send_request(data)  # 返回response
  File "D:\PyApi_heartdub\Number\New_testApi\lib\sendrequest.py", line 38, in send_request
    logging.error("错误信息",error)
Message: '错误信息'
Arguments: (AttributeError("'str' object has no attribute 'items'"),)
--- Logging error ---
Traceback (most recent call last):
  File "D:\PyApi_heartdub\Number\New_testApi\lib\sendrequest.py", line 26, in send_request
    re = s.request(method=method, url="http://one.heartdub.cn:8082"+url, headers=header, data=body_data)
  File "C:\Users\YuanhuaMu\PycharmProjects\pythonProject\venv\lib\site-packages\requests\sessions.py", line 528, in request
    prep = self.prepare_request(req)
  File "C:\Users\YuanhuaMu\PycharmProjects\pythonProject\venv\lib\site-packages\requests\sessions.py", line 456, in prepare_request
    p.prepare(
  File "C:\Users\YuanhuaMu\PycharmProjects\pythonProject\venv\lib\site-packages\requests\models.py", line 317, in prepare
    self.prepare_headers(headers)
  File "C:\Users\YuanhuaMu\PycharmProjects\pythonProject\venv\lib\site-packages\requests\models.py", line 449, in prepare_headers
    for header in headers.items():
AttributeError: 'str' object has no attribute 'items'

During handling of the above exception, another exception occurred:

Traceback (most recent call last):
  File "C:\Users\YuanhuaMu\AppData\Local\Programs\Python\Python39\lib\logging\__init__.py", line 1083, in emit
    msg = self.format(record)
  File "C:\Users\YuanhuaMu\AppData\Local\Programs\Python\Python39\lib\logging\__init__.py", line 927, in format
    return fmt.format(record)
  File "C:\Users\YuanhuaMu\AppData\Local\Programs\Python\Python39\lib\logging\__init__.py", line 663, in format
    record.message = record.getMessage()
  File "C:\Users\YuanhuaMu\AppData\Local\Programs\Python\Python39\lib\logging\__init__.py", line 367, in getMessage
    msg = msg % self.args
TypeError: not all arguments converted during string formatting
Call stack:
  File "D:\PyApi_heartdub\Number\New_testApi\run_suit.py", line 12, in &lt;module&gt;
    runner.run(suite)
  File "D:\PyApi_heartdub\Number\New_testApi\tools\HTMLTestRunner.py", line 677, in run
    test(result)
  File "C:\Users\YuanhuaMu\AppData\Local\Programs\Python\Python39\lib\unittest\suite.py", line 84, in __call__
    return self.run(*args, **kwds)
  File "C:\Users\YuanhuaMu\AppData\Local\Programs\Python\Python39\lib\unittest\suite.py", line 122, in run
    test(result)
  File "C:\Users\YuanhuaMu\AppData\Local\Programs\Python\Python39\lib\unittest\suite.py", line 84, in __call__
    return self.run(*args, **kwds)
  File "C:\Users\YuanhuaMu\AppData\Local\Programs\Python\Python39\lib\unittest\suite.py", line 122, in run
    test(result)
  File "C:\Users\YuanhuaMu\AppData\Local\Programs\Python\Python39\lib\unittest\case.py", line 653, in __call__
    return self.run(*args, **kwds)
  File "C:\Users\YuanhuaMu\AppData\Local\Programs\Python\Python39\lib\unittest\case.py", line 593, in run
    self._callTestMethod(testMethod)
  File "C:\Users\YuanhuaMu\AppData\Local\Programs\Python\Python39\lib\unittest\case.py", line 550, in _callTestMethod
    method()
  File "C:\Users\YuanhuaMu\PycharmProjects\pythonProject\venv\lib\site-packages\ddt.py", line 182, in wrapper
    return func(self, *args, **kwargs)
  File "D:\PyApi_heartdub\Number\New_testApi\case\testcase.py", line 20, in test_run_case
    self.response = send_request(data)  # 返回response
  File "D:\PyApi_heartdub\Number\New_testApi\lib\sendrequest.py", line 38, in send_request
    logging.error("错误信息",error)
Message: '错误信息'
Arguments: (AttributeError("'str' object has no attribute 'items'"),)
________
Traceback (most recent call last):
  File "C:\Users\YuanhuaMu\PycharmProjects\pythonProject\venv\lib\site-packages\ddt.py", line 182, in wrapper
    return func(self, *args, **kwargs)
  File "D:\PyApi_heartdub\Number\New_testApi\case\testcase.py", line 22, in test_run_case
    logging.info("页面返回信息：%s" % self.response.json())
AttributeError: 'NoneType' object has no attribute 'json'
</pre>
    </div>
    <!--css div popup end-->
    </td>
</tr>

<tr id='ft1.16' class='none'>
    <td class='errorCase'><div class='testcase'>test_run_case_16: 执行测试脚本</div></td>
    <td colspan='5' align='center'>
    <!--css div popup start-->
    <a class="popup_link" onfocus='this.blur();' href="javascript:showTestDetail('div_ft1.16')" >
        错误</a>
    <div id='div_ft1.16' class="popup_window">
        <pre>ft1.16: --- Logging error ---
Traceback (most recent call last):
  File "D:\PyApi_heartdub\Number\New_testApi\lib\sendrequest.py", line 26, in send_request
    re = s.request(method=method, url="http://one.heartdub.cn:8082"+url, headers=header, data=body_data)
  File "C:\Users\YuanhuaMu\PycharmProjects\pythonProject\venv\lib\site-packages\requests\sessions.py", line 528, in request
    prep = self.prepare_request(req)
  File "C:\Users\YuanhuaMu\PycharmProjects\pythonProject\venv\lib\site-packages\requests\sessions.py", line 456, in prepare_request
    p.prepare(
  File "C:\Users\YuanhuaMu\PycharmProjects\pythonProject\venv\lib\site-packages\requests\models.py", line 317, in prepare
    self.prepare_headers(headers)
  File "C:\Users\YuanhuaMu\PycharmProjects\pythonProject\venv\lib\site-packages\requests\models.py", line 449, in prepare_headers
    for header in headers.items():
AttributeError: 'str' object has no attribute 'items'

During handling of the above exception, another exception occurred:

Traceback (most recent call last):
  File "C:\Users\YuanhuaMu\AppData\Local\Programs\Python\Python39\lib\logging\__init__.py", line 1083, in emit
    msg = self.format(record)
  File "C:\Users\YuanhuaMu\AppData\Local\Programs\Python\Python39\lib\logging\__init__.py", line 927, in format
    return fmt.format(record)
  File "C:\Users\YuanhuaMu\AppData\Local\Programs\Python\Python39\lib\logging\__init__.py", line 663, in format
    record.message = record.getMessage()
  File "C:\Users\YuanhuaMu\AppData\Local\Programs\Python\Python39\lib\logging\__init__.py", line 367, in getMessage
    msg = msg % self.args
TypeError: not all arguments converted during string formatting
Call stack:
  File "D:\PyApi_heartdub\Number\New_testApi\run_suit.py", line 12, in &lt;module&gt;
    runner.run(suite)
  File "D:\PyApi_heartdub\Number\New_testApi\tools\HTMLTestRunner.py", line 677, in run
    test(result)
  File "C:\Users\YuanhuaMu\AppData\Local\Programs\Python\Python39\lib\unittest\suite.py", line 84, in __call__
    return self.run(*args, **kwds)
  File "C:\Users\YuanhuaMu\AppData\Local\Programs\Python\Python39\lib\unittest\suite.py", line 122, in run
    test(result)
  File "C:\Users\YuanhuaMu\AppData\Local\Programs\Python\Python39\lib\unittest\suite.py", line 84, in __call__
    return self.run(*args, **kwds)
  File "C:\Users\YuanhuaMu\AppData\Local\Programs\Python\Python39\lib\unittest\suite.py", line 122, in run
    test(result)
  File "C:\Users\YuanhuaMu\AppData\Local\Programs\Python\Python39\lib\unittest\case.py", line 653, in __call__
    return self.run(*args, **kwds)
  File "C:\Users\YuanhuaMu\AppData\Local\Programs\Python\Python39\lib\unittest\case.py", line 593, in run
    self._callTestMethod(testMethod)
  File "C:\Users\YuanhuaMu\AppData\Local\Programs\Python\Python39\lib\unittest\case.py", line 550, in _callTestMethod
    method()
  File "C:\Users\YuanhuaMu\PycharmProjects\pythonProject\venv\lib\site-packages\ddt.py", line 182, in wrapper
    return func(self, *args, **kwargs)
  File "D:\PyApi_heartdub\Number\New_testApi\case\testcase.py", line 20, in test_run_case
    self.response = send_request(data)  # 返回response
  File "D:\PyApi_heartdub\Number\New_testApi\lib\sendrequest.py", line 38, in send_request
    logging.error("错误信息",error)
Message: '错误信息'
Arguments: (AttributeError("'str' object has no attribute 'items'"),)
--- Logging error ---
Traceback (most recent call last):
  File "D:\PyApi_heartdub\Number\New_testApi\lib\sendrequest.py", line 26, in send_request
    re = s.request(method=method, url="http://one.heartdub.cn:8082"+url, headers=header, data=body_data)
  File "C:\Users\YuanhuaMu\PycharmProjects\pythonProject\venv\lib\site-packages\requests\sessions.py", line 528, in request
    prep = self.prepare_request(req)
  File "C:\Users\YuanhuaMu\PycharmProjects\pythonProject\venv\lib\site-packages\requests\sessions.py", line 456, in prepare_request
    p.prepare(
  File "C:\Users\YuanhuaMu\PycharmProjects\pythonProject\venv\lib\site-packages\requests\models.py", line 317, in prepare
    self.prepare_headers(headers)
  File "C:\Users\YuanhuaMu\PycharmProjects\pythonProject\venv\lib\site-packages\requests\models.py", line 449, in prepare_headers
    for header in headers.items():
AttributeError: 'str' object has no attribute 'items'

During handling of the above exception, another exception occurred:

Traceback (most recent call last):
  File "C:\Users\YuanhuaMu\AppData\Local\Programs\Python\Python39\lib\logging\__init__.py", line 1083, in emit
    msg = self.format(record)
  File "C:\Users\YuanhuaMu\AppData\Local\Programs\Python\Python39\lib\logging\__init__.py", line 927, in format
    return fmt.format(record)
  File "C:\Users\YuanhuaMu\AppData\Local\Programs\Python\Python39\lib\logging\__init__.py", line 663, in format
    record.message = record.getMessage()
  File "C:\Users\YuanhuaMu\AppData\Local\Programs\Python\Python39\lib\logging\__init__.py", line 367, in getMessage
    msg = msg % self.args
TypeError: not all arguments converted during string formatting
Call stack:
  File "D:\PyApi_heartdub\Number\New_testApi\run_suit.py", line 12, in &lt;module&gt;
    runner.run(suite)
  File "D:\PyApi_heartdub\Number\New_testApi\tools\HTMLTestRunner.py", line 677, in run
    test(result)
  File "C:\Users\YuanhuaMu\AppData\Local\Programs\Python\Python39\lib\unittest\suite.py", line 84, in __call__
    return self.run(*args, **kwds)
  File "C:\Users\YuanhuaMu\AppData\Local\Programs\Python\Python39\lib\unittest\suite.py", line 122, in run
    test(result)
  File "C:\Users\YuanhuaMu\AppData\Local\Programs\Python\Python39\lib\unittest\suite.py", line 84, in __call__
    return self.run(*args, **kwds)
  File "C:\Users\YuanhuaMu\AppData\Local\Programs\Python\Python39\lib\unittest\suite.py", line 122, in run
    test(result)
  File "C:\Users\YuanhuaMu\AppData\Local\Programs\Python\Python39\lib\unittest\case.py", line 653, in __call__
    return self.run(*args, **kwds)
  File "C:\Users\YuanhuaMu\AppData\Local\Programs\Python\Python39\lib\unittest\case.py", line 593, in run
    self._callTestMethod(testMethod)
  File "C:\Users\YuanhuaMu\AppData\Local\Programs\Python\Python39\lib\unittest\case.py", line 550, in _callTestMethod
    method()
  File "C:\Users\YuanhuaMu\PycharmProjects\pythonProject\venv\lib\site-packages\ddt.py", line 182, in wrapper
    return func(self, *args, **kwargs)
  File "D:\PyApi_heartdub\Number\New_testApi\case\testcase.py", line 20, in test_run_case
    self.response = send_request(data)  # 返回response
  File "D:\PyApi_heartdub\Number\New_testApi\lib\sendrequest.py", line 38, in send_request
    logging.error("错误信息",error)
Message: '错误信息'
Arguments: (AttributeError("'str' object has no attribute 'items'"),)
________
Traceback (most recent call last):
  File "C:\Users\YuanhuaMu\PycharmProjects\pythonProject\venv\lib\site-packages\ddt.py", line 182, in wrapper
    return func(self, *args, **kwargs)
  File "D:\PyApi_heartdub\Number\New_testApi\case\testcase.py", line 22, in test_run_case
    logging.info("页面返回信息：%s" % self.response.json())
AttributeError: 'NoneType' object has no attribute 'json'
</pre>
    </div>
    <!--css div popup end-->
    </td>
</tr>

<tr id='ft1.17' class='none'>
    <td class='errorCase'><div class='testcase'>test_run_case_17: 执行测试脚本</div></td>
    <td colspan='5' align='center'>
    <!--css div popup start-->
    <a class="popup_link" onfocus='this.blur();' href="javascript:showTestDetail('div_ft1.17')" >
        错误</a>
    <div id='div_ft1.17' class="popup_window">
        <pre>ft1.17: --- Logging error ---
Traceback (most recent call last):
  File "D:\PyApi_heartdub\Number\New_testApi\lib\sendrequest.py", line 26, in send_request
    re = s.request(method=method, url="http://one.heartdub.cn:8082"+url, headers=header, data=body_data)
  File "C:\Users\YuanhuaMu\PycharmProjects\pythonProject\venv\lib\site-packages\requests\sessions.py", line 528, in request
    prep = self.prepare_request(req)
  File "C:\Users\YuanhuaMu\PycharmProjects\pythonProject\venv\lib\site-packages\requests\sessions.py", line 456, in prepare_request
    p.prepare(
  File "C:\Users\YuanhuaMu\PycharmProjects\pythonProject\venv\lib\site-packages\requests\models.py", line 317, in prepare
    self.prepare_headers(headers)
  File "C:\Users\YuanhuaMu\PycharmProjects\pythonProject\venv\lib\site-packages\requests\models.py", line 449, in prepare_headers
    for header in headers.items():
AttributeError: 'str' object has no attribute 'items'

During handling of the above exception, another exception occurred:

Traceback (most recent call last):
  File "C:\Users\YuanhuaMu\AppData\Local\Programs\Python\Python39\lib\logging\__init__.py", line 1083, in emit
    msg = self.format(record)
  File "C:\Users\YuanhuaMu\AppData\Local\Programs\Python\Python39\lib\logging\__init__.py", line 927, in format
    return fmt.format(record)
  File "C:\Users\YuanhuaMu\AppData\Local\Programs\Python\Python39\lib\logging\__init__.py", line 663, in format
    record.message = record.getMessage()
  File "C:\Users\YuanhuaMu\AppData\Local\Programs\Python\Python39\lib\logging\__init__.py", line 367, in getMessage
    msg = msg % self.args
TypeError: not all arguments converted during string formatting
Call stack:
  File "D:\PyApi_heartdub\Number\New_testApi\run_suit.py", line 12, in &lt;module&gt;
    runner.run(suite)
  File "D:\PyApi_heartdub\Number\New_testApi\tools\HTMLTestRunner.py", line 677, in run
    test(result)
  File "C:\Users\YuanhuaMu\AppData\Local\Programs\Python\Python39\lib\unittest\suite.py", line 84, in __call__
    return self.run(*args, **kwds)
  File "C:\Users\YuanhuaMu\AppData\Local\Programs\Python\Python39\lib\unittest\suite.py", line 122, in run
    test(result)
  File "C:\Users\YuanhuaMu\AppData\Local\Programs\Python\Python39\lib\unittest\suite.py", line 84, in __call__
    return self.run(*args, **kwds)
  File "C:\Users\YuanhuaMu\AppData\Local\Programs\Python\Python39\lib\unittest\suite.py", line 122, in run
    test(result)
  File "C:\Users\YuanhuaMu\AppData\Local\Programs\Python\Python39\lib\unittest\case.py", line 653, in __call__
    return self.run(*args, **kwds)
  File "C:\Users\YuanhuaMu\AppData\Local\Programs\Python\Python39\lib\unittest\case.py", line 593, in run
    self._callTestMethod(testMethod)
  File "C:\Users\YuanhuaMu\AppData\Local\Programs\Python\Python39\lib\unittest\case.py", line 550, in _callTestMethod
    method()
  File "C:\Users\YuanhuaMu\PycharmProjects\pythonProject\venv\lib\site-packages\ddt.py", line 182, in wrapper
    return func(self, *args, **kwargs)
  File "D:\PyApi_heartdub\Number\New_testApi\case\testcase.py", line 20, in test_run_case
    self.response = send_request(data)  # 返回response
  File "D:\PyApi_heartdub\Number\New_testApi\lib\sendrequest.py", line 38, in send_request
    logging.error("错误信息",error)
Message: '错误信息'
Arguments: (AttributeError("'str' object has no attribute 'items'"),)
--- Logging error ---
Traceback (most recent call last):
  File "D:\PyApi_heartdub\Number\New_testApi\lib\sendrequest.py", line 26, in send_request
    re = s.request(method=method, url="http://one.heartdub.cn:8082"+url, headers=header, data=body_data)
  File "C:\Users\YuanhuaMu\PycharmProjects\pythonProject\venv\lib\site-packages\requests\sessions.py", line 528, in request
    prep = self.prepare_request(req)
  File "C:\Users\YuanhuaMu\PycharmProjects\pythonProject\venv\lib\site-packages\requests\sessions.py", line 456, in prepare_request
    p.prepare(
  File "C:\Users\YuanhuaMu\PycharmProjects\pythonProject\venv\lib\site-packages\requests\models.py", line 317, in prepare
    self.prepare_headers(headers)
  File "C:\Users\YuanhuaMu\PycharmProjects\pythonProject\venv\lib\site-packages\requests\models.py", line 449, in prepare_headers
    for header in headers.items():
AttributeError: 'str' object has no attribute 'items'

During handling of the above exception, another exception occurred:

Traceback (most recent call last):
  File "C:\Users\YuanhuaMu\AppData\Local\Programs\Python\Python39\lib\logging\__init__.py", line 1083, in emit
    msg = self.format(record)
  File "C:\Users\YuanhuaMu\AppData\Local\Programs\Python\Python39\lib\logging\__init__.py", line 927, in format
    return fmt.format(record)
  File "C:\Users\YuanhuaMu\AppData\Local\Programs\Python\Python39\lib\logging\__init__.py", line 663, in format
    record.message = record.getMessage()
  File "C:\Users\YuanhuaMu\AppData\Local\Programs\Python\Python39\lib\logging\__init__.py", line 367, in getMessage
    msg = msg % self.args
TypeError: not all arguments converted during string formatting
Call stack:
  File "D:\PyApi_heartdub\Number\New_testApi\run_suit.py", line 12, in &lt;module&gt;
    runner.run(suite)
  File "D:\PyApi_heartdub\Number\New_testApi\tools\HTMLTestRunner.py", line 677, in run
    test(result)
  File "C:\Users\YuanhuaMu\AppData\Local\Programs\Python\Python39\lib\unittest\suite.py", line 84, in __call__
    return self.run(*args, **kwds)
  File "C:\Users\YuanhuaMu\AppData\Local\Programs\Python\Python39\lib\unittest\suite.py", line 122, in run
    test(result)
  File "C:\Users\YuanhuaMu\AppData\Local\Programs\Python\Python39\lib\unittest\suite.py", line 84, in __call__
    return self.run(*args, **kwds)
  File "C:\Users\YuanhuaMu\AppData\Local\Programs\Python\Python39\lib\unittest\suite.py", line 122, in run
    test(result)
  File "C:\Users\YuanhuaMu\AppData\Local\Programs\Python\Python39\lib\unittest\case.py", line 653, in __call__
    return self.run(*args, **kwds)
  File "C:\Users\YuanhuaMu\AppData\Local\Programs\Python\Python39\lib\unittest\case.py", line 593, in run
    self._callTestMethod(testMethod)
  File "C:\Users\YuanhuaMu\AppData\Local\Programs\Python\Python39\lib\unittest\case.py", line 550, in _callTestMethod
    method()
  File "C:\Users\YuanhuaMu\PycharmProjects\pythonProject\venv\lib\site-packages\ddt.py", line 182, in wrapper
    return func(self, *args, **kwargs)
  File "D:\PyApi_heartdub\Number\New_testApi\case\testcase.py", line 20, in test_run_case
    self.response = send_request(data)  # 返回response
  File "D:\PyApi_heartdub\Number\New_testApi\lib\sendrequest.py", line 38, in send_request
    logging.error("错误信息",error)
Message: '错误信息'
Arguments: (AttributeError("'str' object has no attribute 'items'"),)
________
Traceback (most recent call last):
  File "C:\Users\YuanhuaMu\PycharmProjects\pythonProject\venv\lib\site-packages\ddt.py", line 182, in wrapper
    return func(self, *args, **kwargs)
  File "D:\PyApi_heartdub\Number\New_testApi\case\testcase.py", line 22, in test_run_case
    logging.info("页面返回信息：%s" % self.response.json())
AttributeError: 'NoneType' object has no attribute 'json'
</pre>
    </div>
    <!--css div popup end-->
    </td>
</tr>

<tr id='ft1.18' class='none'>
    <td class='errorCase'><div class='testcase'>test_run_case_18: 执行测试脚本</div></td>
    <td colspan='5' align='center'>
    <!--css div popup start-->
    <a class="popup_link" onfocus='this.blur();' href="javascript:showTestDetail('div_ft1.18')" >
        错误</a>
    <div id='div_ft1.18' class="popup_window">
        <pre>ft1.18: --- Logging error ---
Traceback (most recent call last):
  File "D:\PyApi_heartdub\Number\New_testApi\lib\sendrequest.py", line 26, in send_request
    re = s.request(method=method, url="http://one.heartdub.cn:8082"+url, headers=header, data=body_data)
  File "C:\Users\YuanhuaMu\PycharmProjects\pythonProject\venv\lib\site-packages\requests\sessions.py", line 528, in request
    prep = self.prepare_request(req)
  File "C:\Users\YuanhuaMu\PycharmProjects\pythonProject\venv\lib\site-packages\requests\sessions.py", line 456, in prepare_request
    p.prepare(
  File "C:\Users\YuanhuaMu\PycharmProjects\pythonProject\venv\lib\site-packages\requests\models.py", line 317, in prepare
    self.prepare_headers(headers)
  File "C:\Users\YuanhuaMu\PycharmProjects\pythonProject\venv\lib\site-packages\requests\models.py", line 449, in prepare_headers
    for header in headers.items():
AttributeError: 'str' object has no attribute 'items'

During handling of the above exception, another exception occurred:

Traceback (most recent call last):
  File "C:\Users\YuanhuaMu\AppData\Local\Programs\Python\Python39\lib\logging\__init__.py", line 1083, in emit
    msg = self.format(record)
  File "C:\Users\YuanhuaMu\AppData\Local\Programs\Python\Python39\lib\logging\__init__.py", line 927, in format
    return fmt.format(record)
  File "C:\Users\YuanhuaMu\AppData\Local\Programs\Python\Python39\lib\logging\__init__.py", line 663, in format
    record.message = record.getMessage()
  File "C:\Users\YuanhuaMu\AppData\Local\Programs\Python\Python39\lib\logging\__init__.py", line 367, in getMessage
    msg = msg % self.args
TypeError: not all arguments converted during string formatting
Call stack:
  File "D:\PyApi_heartdub\Number\New_testApi\run_suit.py", line 12, in &lt;module&gt;
    runner.run(suite)
  File "D:\PyApi_heartdub\Number\New_testApi\tools\HTMLTestRunner.py", line 677, in run
    test(result)
  File "C:\Users\YuanhuaMu\AppData\Local\Programs\Python\Python39\lib\unittest\suite.py", line 84, in __call__
    return self.run(*args, **kwds)
  File "C:\Users\YuanhuaMu\AppData\Local\Programs\Python\Python39\lib\unittest\suite.py", line 122, in run
    test(result)
  File "C:\Users\YuanhuaMu\AppData\Local\Programs\Python\Python39\lib\unittest\suite.py", line 84, in __call__
    return self.run(*args, **kwds)
  File "C:\Users\YuanhuaMu\AppData\Local\Programs\Python\Python39\lib\unittest\suite.py", line 122, in run
    test(result)
  File "C:\Users\YuanhuaMu\AppData\Local\Programs\Python\Python39\lib\unittest\case.py", line 653, in __call__
    return self.run(*args, **kwds)
  File "C:\Users\YuanhuaMu\AppData\Local\Programs\Python\Python39\lib\unittest\case.py", line 593, in run
    self._callTestMethod(testMethod)
  File "C:\Users\YuanhuaMu\AppData\Local\Programs\Python\Python39\lib\unittest\case.py", line 550, in _callTestMethod
    method()
  File "C:\Users\YuanhuaMu\PycharmProjects\pythonProject\venv\lib\site-packages\ddt.py", line 182, in wrapper
    return func(self, *args, **kwargs)
  File "D:\PyApi_heartdub\Number\New_testApi\case\testcase.py", line 20, in test_run_case
    self.response = send_request(data)  # 返回response
  File "D:\PyApi_heartdub\Number\New_testApi\lib\sendrequest.py", line 38, in send_request
    logging.error("错误信息",error)
Message: '错误信息'
Arguments: (AttributeError("'str' object has no attribute 'items'"),)
--- Logging error ---
Traceback (most recent call last):
  File "D:\PyApi_heartdub\Number\New_testApi\lib\sendrequest.py", line 26, in send_request
    re = s.request(method=method, url="http://one.heartdub.cn:8082"+url, headers=header, data=body_data)
  File "C:\Users\YuanhuaMu\PycharmProjects\pythonProject\venv\lib\site-packages\requests\sessions.py", line 528, in request
    prep = self.prepare_request(req)
  File "C:\Users\YuanhuaMu\PycharmProjects\pythonProject\venv\lib\site-packages\requests\sessions.py", line 456, in prepare_request
    p.prepare(
  File "C:\Users\YuanhuaMu\PycharmProjects\pythonProject\venv\lib\site-packages\requests\models.py", line 317, in prepare
    self.prepare_headers(headers)
  File "C:\Users\YuanhuaMu\PycharmProjects\pythonProject\venv\lib\site-packages\requests\models.py", line 449, in prepare_headers
    for header in headers.items():
AttributeError: 'str' object has no attribute 'items'

During handling of the above exception, another exception occurred:

Traceback (most recent call last):
  File "C:\Users\YuanhuaMu\AppData\Local\Programs\Python\Python39\lib\logging\__init__.py", line 1083, in emit
    msg = self.format(record)
  File "C:\Users\YuanhuaMu\AppData\Local\Programs\Python\Python39\lib\logging\__init__.py", line 927, in format
    return fmt.format(record)
  File "C:\Users\YuanhuaMu\AppData\Local\Programs\Python\Python39\lib\logging\__init__.py", line 663, in format
    record.message = record.getMessage()
  File "C:\Users\YuanhuaMu\AppData\Local\Programs\Python\Python39\lib\logging\__init__.py", line 367, in getMessage
    msg = msg % self.args
TypeError: not all arguments converted during string formatting
Call stack:
  File "D:\PyApi_heartdub\Number\New_testApi\run_suit.py", line 12, in &lt;module&gt;
    runner.run(suite)
  File "D:\PyApi_heartdub\Number\New_testApi\tools\HTMLTestRunner.py", line 677, in run
    test(result)
  File "C:\Users\YuanhuaMu\AppData\Local\Programs\Python\Python39\lib\unittest\suite.py", line 84, in __call__
    return self.run(*args, **kwds)
  File "C:\Users\YuanhuaMu\AppData\Local\Programs\Python\Python39\lib\unittest\suite.py", line 122, in run
    test(result)
  File "C:\Users\YuanhuaMu\AppData\Local\Programs\Python\Python39\lib\unittest\suite.py", line 84, in __call__
    return self.run(*args, **kwds)
  File "C:\Users\YuanhuaMu\AppData\Local\Programs\Python\Python39\lib\unittest\suite.py", line 122, in run
    test(result)
  File "C:\Users\YuanhuaMu\AppData\Local\Programs\Python\Python39\lib\unittest\case.py", line 653, in __call__
    return self.run(*args, **kwds)
  File "C:\Users\YuanhuaMu\AppData\Local\Programs\Python\Python39\lib\unittest\case.py", line 593, in run
    self._callTestMethod(testMethod)
  File "C:\Users\YuanhuaMu\AppData\Local\Programs\Python\Python39\lib\unittest\case.py", line 550, in _callTestMethod
    method()
  File "C:\Users\YuanhuaMu\PycharmProjects\pythonProject\venv\lib\site-packages\ddt.py", line 182, in wrapper
    return func(self, *args, **kwargs)
  File "D:\PyApi_heartdub\Number\New_testApi\case\testcase.py", line 20, in test_run_case
    self.response = send_request(data)  # 返回response
  File "D:\PyApi_heartdub\Number\New_testApi\lib\sendrequest.py", line 38, in send_request
    logging.error("错误信息",error)
Message: '错误信息'
Arguments: (AttributeError("'str' object has no attribute 'items'"),)
________
Traceback (most recent call last):
  File "C:\Users\YuanhuaMu\PycharmProjects\pythonProject\venv\lib\site-packages\ddt.py", line 182, in wrapper
    return func(self, *args, **kwargs)
  File "D:\PyApi_heartdub\Number\New_testApi\case\testcase.py", line 22, in test_run_case
    logging.info("页面返回信息：%s" % self.response.json())
AttributeError: 'NoneType' object has no attribute 'json'
</pre>
    </div>
    <!--css div popup end-->
    </td>
</tr>

<tr id='ft1.19' class='none'>
    <td class='errorCase'><div class='testcase'>test_run_case_19: 执行测试脚本</div></td>
    <td colspan='5' align='center'>
    <!--css div popup start-->
    <a class="popup_link" onfocus='this.blur();' href="javascript:showTestDetail('div_ft1.19')" >
        错误</a>
    <div id='div_ft1.19' class="popup_window">
        <pre>ft1.19: --- Logging error ---
Traceback (most recent call last):
  File "D:\PyApi_heartdub\Number\New_testApi\lib\sendrequest.py", line 26, in send_request
    re = s.request(method=method, url="http://one.heartdub.cn:8082"+url, headers=header, data=body_data)
  File "C:\Users\YuanhuaMu\PycharmProjects\pythonProject\venv\lib\site-packages\requests\sessions.py", line 528, in request
    prep = self.prepare_request(req)
  File "C:\Users\YuanhuaMu\PycharmProjects\pythonProject\venv\lib\site-packages\requests\sessions.py", line 456, in prepare_request
    p.prepare(
  File "C:\Users\YuanhuaMu\PycharmProjects\pythonProject\venv\lib\site-packages\requests\models.py", line 317, in prepare
    self.prepare_headers(headers)
  File "C:\Users\YuanhuaMu\PycharmProjects\pythonProject\venv\lib\site-packages\requests\models.py", line 449, in prepare_headers
    for header in headers.items():
AttributeError: 'str' object has no attribute 'items'

During handling of the above exception, another exception occurred:

Traceback (most recent call last):
  File "C:\Users\YuanhuaMu\AppData\Local\Programs\Python\Python39\lib\logging\__init__.py", line 1083, in emit
    msg = self.format(record)
  File "C:\Users\YuanhuaMu\AppData\Local\Programs\Python\Python39\lib\logging\__init__.py", line 927, in format
    return fmt.format(record)
  File "C:\Users\YuanhuaMu\AppData\Local\Programs\Python\Python39\lib\logging\__init__.py", line 663, in format
    record.message = record.getMessage()
  File "C:\Users\YuanhuaMu\AppData\Local\Programs\Python\Python39\lib\logging\__init__.py", line 367, in getMessage
    msg = msg % self.args
TypeError: not all arguments converted during string formatting
Call stack:
  File "D:\PyApi_heartdub\Number\New_testApi\run_suit.py", line 12, in &lt;module&gt;
    runner.run(suite)
  File "D:\PyApi_heartdub\Number\New_testApi\tools\HTMLTestRunner.py", line 677, in run
    test(result)
  File "C:\Users\YuanhuaMu\AppData\Local\Programs\Python\Python39\lib\unittest\suite.py", line 84, in __call__
    return self.run(*args, **kwds)
  File "C:\Users\YuanhuaMu\AppData\Local\Programs\Python\Python39\lib\unittest\suite.py", line 122, in run
    test(result)
  File "C:\Users\YuanhuaMu\AppData\Local\Programs\Python\Python39\lib\unittest\suite.py", line 84, in __call__
    return self.run(*args, **kwds)
  File "C:\Users\YuanhuaMu\AppData\Local\Programs\Python\Python39\lib\unittest\suite.py", line 122, in run
    test(result)
  File "C:\Users\YuanhuaMu\AppData\Local\Programs\Python\Python39\lib\unittest\case.py", line 653, in __call__
    return self.run(*args, **kwds)
  File "C:\Users\YuanhuaMu\AppData\Local\Programs\Python\Python39\lib\unittest\case.py", line 593, in run
    self._callTestMethod(testMethod)
  File "C:\Users\YuanhuaMu\AppData\Local\Programs\Python\Python39\lib\unittest\case.py", line 550, in _callTestMethod
    method()
  File "C:\Users\YuanhuaMu\PycharmProjects\pythonProject\venv\lib\site-packages\ddt.py", line 182, in wrapper
    return func(self, *args, **kwargs)
  File "D:\PyApi_heartdub\Number\New_testApi\case\testcase.py", line 20, in test_run_case
    self.response = send_request(data)  # 返回response
  File "D:\PyApi_heartdub\Number\New_testApi\lib\sendrequest.py", line 38, in send_request
    logging.error("错误信息",error)
Message: '错误信息'
Arguments: (AttributeError("'str' object has no attribute 'items'"),)
--- Logging error ---
Traceback (most recent call last):
  File "D:\PyApi_heartdub\Number\New_testApi\lib\sendrequest.py", line 26, in send_request
    re = s.request(method=method, url="http://one.heartdub.cn:8082"+url, headers=header, data=body_data)
  File "C:\Users\YuanhuaMu\PycharmProjects\pythonProject\venv\lib\site-packages\requests\sessions.py", line 528, in request
    prep = self.prepare_request(req)
  File "C:\Users\YuanhuaMu\PycharmProjects\pythonProject\venv\lib\site-packages\requests\sessions.py", line 456, in prepare_request
    p.prepare(
  File "C:\Users\YuanhuaMu\PycharmProjects\pythonProject\venv\lib\site-packages\requests\models.py", line 317, in prepare
    self.prepare_headers(headers)
  File "C:\Users\YuanhuaMu\PycharmProjects\pythonProject\venv\lib\site-packages\requests\models.py", line 449, in prepare_headers
    for header in headers.items():
AttributeError: 'str' object has no attribute 'items'

During handling of the above exception, another exception occurred:

Traceback (most recent call last):
  File "C:\Users\YuanhuaMu\AppData\Local\Programs\Python\Python39\lib\logging\__init__.py", line 1083, in emit
    msg = self.format(record)
  File "C:\Users\YuanhuaMu\AppData\Local\Programs\Python\Python39\lib\logging\__init__.py", line 927, in format
    return fmt.format(record)
  File "C:\Users\YuanhuaMu\AppData\Local\Programs\Python\Python39\lib\logging\__init__.py", line 663, in format
    record.message = record.getMessage()
  File "C:\Users\YuanhuaMu\AppData\Local\Programs\Python\Python39\lib\logging\__init__.py", line 367, in getMessage
    msg = msg % self.args
TypeError: not all arguments converted during string formatting
Call stack:
  File "D:\PyApi_heartdub\Number\New_testApi\run_suit.py", line 12, in &lt;module&gt;
    runner.run(suite)
  File "D:\PyApi_heartdub\Number\New_testApi\tools\HTMLTestRunner.py", line 677, in run
    test(result)
  File "C:\Users\YuanhuaMu\AppData\Local\Programs\Python\Python39\lib\unittest\suite.py", line 84, in __call__
    return self.run(*args, **kwds)
  File "C:\Users\YuanhuaMu\AppData\Local\Programs\Python\Python39\lib\unittest\suite.py", line 122, in run
    test(result)
  File "C:\Users\YuanhuaMu\AppData\Local\Programs\Python\Python39\lib\unittest\suite.py", line 84, in __call__
    return self.run(*args, **kwds)
  File "C:\Users\YuanhuaMu\AppData\Local\Programs\Python\Python39\lib\unittest\suite.py", line 122, in run
    test(result)
  File "C:\Users\YuanhuaMu\AppData\Local\Programs\Python\Python39\lib\unittest\case.py", line 653, in __call__
    return self.run(*args, **kwds)
  File "C:\Users\YuanhuaMu\AppData\Local\Programs\Python\Python39\lib\unittest\case.py", line 593, in run
    self._callTestMethod(testMethod)
  File "C:\Users\YuanhuaMu\AppData\Local\Programs\Python\Python39\lib\unittest\case.py", line 550, in _callTestMethod
    method()
  File "C:\Users\YuanhuaMu\PycharmProjects\pythonProject\venv\lib\site-packages\ddt.py", line 182, in wrapper
    return func(self, *args, **kwargs)
  File "D:\PyApi_heartdub\Number\New_testApi\case\testcase.py", line 20, in test_run_case
    self.response = send_request(data)  # 返回response
  File "D:\PyApi_heartdub\Number\New_testApi\lib\sendrequest.py", line 38, in send_request
    logging.error("错误信息",error)
Message: '错误信息'
Arguments: (AttributeError("'str' object has no attribute 'items'"),)
________
Traceback (most recent call last):
  File "C:\Users\YuanhuaMu\PycharmProjects\pythonProject\venv\lib\site-packages\ddt.py", line 182, in wrapper
    return func(self, *args, **kwargs)
  File "D:\PyApi_heartdub\Number\New_testApi\case\testcase.py", line 22, in test_run_case
    logging.info("页面返回信息：%s" % self.response.json())
AttributeError: 'NoneType' object has no attribute 'json'
</pre>
    </div>
    <!--css div popup end-->
    </td>
</tr>

        <tr id='total_row'>
            <td>总计</td>
            <td>19</td>
            <td>0</td>
            <td>0</td>
            <td>19</td>
            <td>&nbsp;</td>
        </tr>
    </table>

        <div id='ending'>&nbsp;</div>
        
    <script type="text/javascript">
        // 基于准备好的dom，初始化echarts实例
        var myChart = echarts.init(document.getElementById('chart'));
        // 指定图表的配置项和数据
        var option = {
            title : {
                text: '测试执行情况',
                x:'center'
            },
            tooltip : {
                trigger: 'item',
                formatter: "{a} <br/>{b} : {c} ({d}%)"
            },
            color: ['#95b75d', 'grey', '#b64645'],
            legend: {
                orient: 'vertical',
                left: 'left',
                data: ['通过','失败','错误']
            },
            series : [
                {
                    name: '测试执行情况',
                    type: 'pie',
                    radius : '60%',
                    center: ['50%', '60%'],
                    data:[
                        {value:0, name:'通过'},
                        {value:0, name:'失败'},
                        {value:19, name:'错误'}
                    ],
                    itemStyle: {
                        emphasis: {
                            shadowBlur: 10,
                            shadowOffsetX: 0,
                            shadowColor: 'rgba(0, 0, 0, 0.5)'
                        }
                    }
                }
            ]
        };
        // 使用刚指定的配置项和数据显示图表。
        myChart.setOption(option);
    </script>
    
    </div>
</body>
</html>
